[2023-03-10 01:17:24,369] {taskinstance.py:1159} INFO - Dependencies all met for <TaskInstance: pipeline_bash_operator.run_script_transform manual__2023-03-10T01:17:04.024131+00:00 [queued]>
[2023-03-10 01:17:24,375] {taskinstance.py:1159} INFO - Dependencies all met for <TaskInstance: pipeline_bash_operator.run_script_transform manual__2023-03-10T01:17:04.024131+00:00 [queued]>
[2023-03-10 01:17:24,376] {taskinstance.py:1356} INFO - 
--------------------------------------------------------------------------------
[2023-03-10 01:17:24,377] {taskinstance.py:1357} INFO - Starting attempt 1 of 1
[2023-03-10 01:17:24,378] {taskinstance.py:1358} INFO - 
--------------------------------------------------------------------------------
[2023-03-10 01:17:24,385] {taskinstance.py:1377} INFO - Executing <Task(BashOperator): run_script_transform> on 2023-03-10 01:17:04.024131+00:00
[2023-03-10 01:17:24,389] {standard_task_runner.py:52} INFO - Started process 1130 to run task
[2023-03-10 01:17:24,391] {standard_task_runner.py:79} INFO - Running: ['***', 'tasks', 'run', 'pipeline_bash_operator', 'run_script_transform', 'manual__2023-03-10T01:17:04.024131+00:00', '--job-id', '75', '--raw', '--subdir', 'DAGS_FOLDER/pipeline_bash_operator.py', '--cfg-path', '/tmp/tmpqc9bhkf6', '--error-file', '/tmp/tmpfbh89ngh']
[2023-03-10 01:17:24,392] {standard_task_runner.py:80} INFO - Job 75: Subtask run_script_transform
[2023-03-10 01:17:24,430] {task_command.py:369} INFO - Running <TaskInstance: pipeline_bash_operator.run_script_transform manual__2023-03-10T01:17:04.024131+00:00 [running]> on host 477ef5e408be
[2023-03-10 01:17:24,474] {taskinstance.py:1571} INFO - Exporting the following env vars:
AIRFLOW_CTX_DAG_OWNER=Americo
AIRFLOW_CTX_DAG_ID=pipeline_bash_operator
AIRFLOW_CTX_TASK_ID=run_script_transform
AIRFLOW_CTX_EXECUTION_DATE=2023-03-10T01:17:04.024131+00:00
AIRFLOW_CTX_TRY_NUMBER=1
AIRFLOW_CTX_DAG_RUN_ID=manual__2023-03-10T01:17:04.024131+00:00
[2023-03-10 01:17:24,476] {subprocess.py:62} INFO - Tmp dir root location: 
 /tmp
[2023-03-10 01:17:24,477] {subprocess.py:74} INFO - Running command: ['bash', '-c', 'python /opt/***/dags/Proyecto/transform.py']
[2023-03-10 01:17:24,484] {subprocess.py:85} INFO - Output:
[2023-03-10 01:17:51,713] {subprocess.py:92} INFO - ingest loaded
[2023-03-10 01:17:51,716] {subprocess.py:92} INFO - loaded adsl landing
[2023-03-10 01:17:51,720] {subprocess.py:92} INFO - transform loaded
[2023-03-10 01:17:51,722] {subprocess.py:92} INFO - loaded adsl gold
[2023-03-10 01:17:51,727] {subprocess.py:92} INFO - Traceback (most recent call last):
[2023-03-10 01:17:51,728] {subprocess.py:92} INFO -   File "/home/***/.local/lib/python3.7/site-packages/pymysql/connections.py", line 614, in connect
[2023-03-10 01:17:51,729] {subprocess.py:92} INFO -     (self.host, self.port), self.connect_timeout, **kwargs
[2023-03-10 01:17:51,730] {subprocess.py:92} INFO -   File "/usr/local/lib/python3.7/socket.py", line 728, in create_connection
[2023-03-10 01:17:51,732] {subprocess.py:92} INFO -     raise err
[2023-03-10 01:17:51,733] {subprocess.py:92} INFO -   File "/usr/local/lib/python3.7/socket.py", line 716, in create_connection
[2023-03-10 01:17:51,734] {subprocess.py:92} INFO -     sock.connect(sa)
[2023-03-10 01:17:51,735] {subprocess.py:92} INFO - ConnectionRefusedError: [Errno 111] Connection refused
[2023-03-10 01:17:51,737] {subprocess.py:92} INFO - 
[2023-03-10 01:17:51,738] {subprocess.py:92} INFO - During handling of the above exception, another exception occurred:
[2023-03-10 01:17:51,739] {subprocess.py:92} INFO - 
[2023-03-10 01:17:51,740] {subprocess.py:92} INFO - Traceback (most recent call last):
[2023-03-10 01:17:51,741] {subprocess.py:92} INFO -   File "/home/***/.local/lib/python3.7/site-packages/sqlalchemy/engine/base.py", line 3141, in _wrap_pool_connect
[2023-03-10 01:17:51,742] {subprocess.py:92} INFO -     return fn()
[2023-03-10 01:17:51,744] {subprocess.py:92} INFO -   File "/home/***/.local/lib/python3.7/site-packages/sqlalchemy/pool/base.py", line 301, in connect
[2023-03-10 01:17:51,745] {subprocess.py:92} INFO -     return _ConnectionFairy._checkout(self)
[2023-03-10 01:17:51,747] {subprocess.py:92} INFO -   File "/home/***/.local/lib/python3.7/site-packages/sqlalchemy/pool/base.py", line 755, in _checkout
[2023-03-10 01:17:51,748] {subprocess.py:92} INFO -     fairy = _ConnectionRecord.checkout(pool)
[2023-03-10 01:17:51,749] {subprocess.py:92} INFO -   File "/home/***/.local/lib/python3.7/site-packages/sqlalchemy/pool/base.py", line 419, in checkout
[2023-03-10 01:17:51,750] {subprocess.py:92} INFO -     rec = pool._do_get()
[2023-03-10 01:17:51,751] {subprocess.py:92} INFO -   File "/home/***/.local/lib/python3.7/site-packages/sqlalchemy/pool/impl.py", line 145, in _do_get
[2023-03-10 01:17:51,752] {subprocess.py:92} INFO -     self._dec_overflow()
[2023-03-10 01:17:51,753] {subprocess.py:92} INFO -   File "/home/***/.local/lib/python3.7/site-packages/sqlalchemy/util/langhelpers.py", line 72, in __exit__
[2023-03-10 01:17:51,754] {subprocess.py:92} INFO -     with_traceback=exc_tb,
[2023-03-10 01:17:51,755] {subprocess.py:92} INFO -   File "/home/***/.local/lib/python3.7/site-packages/sqlalchemy/util/compat.py", line 211, in raise_
[2023-03-10 01:17:51,756] {subprocess.py:92} INFO -     raise exception
[2023-03-10 01:17:51,756] {subprocess.py:92} INFO -   File "/home/***/.local/lib/python3.7/site-packages/sqlalchemy/pool/impl.py", line 142, in _do_get
[2023-03-10 01:17:51,758] {subprocess.py:92} INFO -     return self._create_connection()
[2023-03-10 01:17:51,758] {subprocess.py:92} INFO -   File "/home/***/.local/lib/python3.7/site-packages/sqlalchemy/pool/base.py", line 247, in _create_connection
[2023-03-10 01:17:51,759] {subprocess.py:92} INFO -     return _ConnectionRecord(self)
[2023-03-10 01:17:51,760] {subprocess.py:92} INFO -   File "/home/***/.local/lib/python3.7/site-packages/sqlalchemy/pool/base.py", line 362, in __init__
[2023-03-10 01:17:51,761] {subprocess.py:92} INFO -     self.__connect(first_connect_check=True)
[2023-03-10 01:17:51,762] {subprocess.py:92} INFO -   File "/home/***/.local/lib/python3.7/site-packages/sqlalchemy/pool/base.py", line 605, in __connect
[2023-03-10 01:17:51,763] {subprocess.py:92} INFO -     pool.logger.debug("Error on connect(): %s", e)
[2023-03-10 01:17:51,764] {subprocess.py:92} INFO -   File "/home/***/.local/lib/python3.7/site-packages/sqlalchemy/util/langhelpers.py", line 72, in __exit__
[2023-03-10 01:17:51,765] {subprocess.py:92} INFO -     with_traceback=exc_tb,
[2023-03-10 01:17:51,765] {subprocess.py:92} INFO -   File "/home/***/.local/lib/python3.7/site-packages/sqlalchemy/util/compat.py", line 211, in raise_
[2023-03-10 01:17:51,766] {subprocess.py:92} INFO -     raise exception
[2023-03-10 01:17:51,767] {subprocess.py:92} INFO -   File "/home/***/.local/lib/python3.7/site-packages/sqlalchemy/pool/base.py", line 599, in __connect
[2023-03-10 01:17:51,768] {subprocess.py:92} INFO -     connection = pool._invoke_creator(self)
[2023-03-10 01:17:51,769] {subprocess.py:92} INFO -   File "/home/***/.local/lib/python3.7/site-packages/sqlalchemy/engine/create.py", line 578, in connect
[2023-03-10 01:17:51,770] {subprocess.py:92} INFO -     return dialect.connect(*cargs, **cparams)
[2023-03-10 01:17:51,771] {subprocess.py:92} INFO -   File "/home/***/.local/lib/python3.7/site-packages/sqlalchemy/engine/default.py", line 583, in connect
[2023-03-10 01:17:51,771] {subprocess.py:92} INFO -     return self.dbapi.connect(*cargs, **cparams)
[2023-03-10 01:17:51,772] {subprocess.py:92} INFO -   File "/home/***/.local/lib/python3.7/site-packages/pymysql/connections.py", line 353, in __init__
[2023-03-10 01:17:51,773] {subprocess.py:92} INFO -     self.connect()
[2023-03-10 01:17:51,774] {subprocess.py:92} INFO -   File "/home/***/.local/lib/python3.7/site-packages/pymysql/connections.py", line 664, in connect
[2023-03-10 01:17:51,774] {subprocess.py:92} INFO -     raise exc
[2023-03-10 01:17:51,775] {subprocess.py:92} INFO - pymysql.err.OperationalError: (2003, "Can't connect to MySQL server on '127.0.0.1' ([Errno 111] Connection refused)")
[2023-03-10 01:17:51,776] {subprocess.py:92} INFO - 
[2023-03-10 01:17:51,777] {subprocess.py:92} INFO - The above exception was the direct cause of the following exception:
[2023-03-10 01:17:51,778] {subprocess.py:92} INFO - 
[2023-03-10 01:17:51,779] {subprocess.py:92} INFO - Traceback (most recent call last):
[2023-03-10 01:17:51,780] {subprocess.py:92} INFO -   File "/opt/***/dags/Proyecto/transform.py", line 33, in <module>
[2023-03-10 01:17:51,781] {subprocess.py:92} INFO -     u.create_mysql_tbl_schema(df_enunciado1, u.mysql_conn(u.mysql_engine()), 'retail', "enunciado1")
[2023-03-10 01:17:51,782] {subprocess.py:92} INFO -   File "/opt/***/dags/Proyecto/process/util/utils.py", line 28, in mysql_conn
[2023-03-10 01:17:51,783] {subprocess.py:92} INFO -     conn = engine.raw_connection()
[2023-03-10 01:17:51,784] {subprocess.py:92} INFO -   File "/home/***/.local/lib/python3.7/site-packages/sqlalchemy/engine/base.py", line 3174, in raw_connection
[2023-03-10 01:17:51,784] {subprocess.py:92} INFO -     return self._wrap_pool_connect(self.pool.connect, _connection)
[2023-03-10 01:17:51,786] {subprocess.py:92} INFO -   File "/home/***/.local/lib/python3.7/site-packages/sqlalchemy/engine/base.py", line 3145, in _wrap_pool_connect
[2023-03-10 01:17:51,786] {subprocess.py:92} INFO -     e, dialect, self
[2023-03-10 01:17:51,787] {subprocess.py:92} INFO -   File "/home/***/.local/lib/python3.7/site-packages/sqlalchemy/engine/base.py", line 2004, in _handle_dbapi_exception_noconnection
[2023-03-10 01:17:51,790] {subprocess.py:92} INFO -     sqlalchemy_exception, with_traceback=exc_info[2], from_=e
[2023-03-10 01:17:51,791] {subprocess.py:92} INFO -   File "/home/***/.local/lib/python3.7/site-packages/sqlalchemy/util/compat.py", line 211, in raise_
[2023-03-10 01:17:51,792] {subprocess.py:92} INFO -     raise exception
[2023-03-10 01:17:51,793] {subprocess.py:92} INFO -   File "/home/***/.local/lib/python3.7/site-packages/sqlalchemy/engine/base.py", line 3141, in _wrap_pool_connect
[2023-03-10 01:17:51,793] {subprocess.py:92} INFO -     return fn()
[2023-03-10 01:17:51,794] {subprocess.py:92} INFO -   File "/home/***/.local/lib/python3.7/site-packages/sqlalchemy/pool/base.py", line 301, in connect
[2023-03-10 01:17:51,795] {subprocess.py:92} INFO -     return _ConnectionFairy._checkout(self)
[2023-03-10 01:17:51,796] {subprocess.py:92} INFO -   File "/home/***/.local/lib/python3.7/site-packages/sqlalchemy/pool/base.py", line 755, in _checkout
[2023-03-10 01:17:51,797] {subprocess.py:92} INFO -     fairy = _ConnectionRecord.checkout(pool)
[2023-03-10 01:17:51,798] {subprocess.py:92} INFO -   File "/home/***/.local/lib/python3.7/site-packages/sqlalchemy/pool/base.py", line 419, in checkout
[2023-03-10 01:17:51,799] {subprocess.py:92} INFO -     rec = pool._do_get()
[2023-03-10 01:17:51,799] {subprocess.py:92} INFO -   File "/home/***/.local/lib/python3.7/site-packages/sqlalchemy/pool/impl.py", line 145, in _do_get
[2023-03-10 01:17:51,800] {subprocess.py:92} INFO -     self._dec_overflow()
[2023-03-10 01:17:51,801] {subprocess.py:92} INFO -   File "/home/***/.local/lib/python3.7/site-packages/sqlalchemy/util/langhelpers.py", line 72, in __exit__
[2023-03-10 01:17:51,802] {subprocess.py:92} INFO -     with_traceback=exc_tb,
[2023-03-10 01:17:51,803] {subprocess.py:92} INFO -   File "/home/***/.local/lib/python3.7/site-packages/sqlalchemy/util/compat.py", line 211, in raise_
[2023-03-10 01:17:51,803] {subprocess.py:92} INFO -     raise exception
[2023-03-10 01:17:51,804] {subprocess.py:92} INFO -   File "/home/***/.local/lib/python3.7/site-packages/sqlalchemy/pool/impl.py", line 142, in _do_get
[2023-03-10 01:17:51,805] {subprocess.py:92} INFO -     return self._create_connection()
[2023-03-10 01:17:51,805] {subprocess.py:92} INFO -   File "/home/***/.local/lib/python3.7/site-packages/sqlalchemy/pool/base.py", line 247, in _create_connection
[2023-03-10 01:17:51,806] {subprocess.py:92} INFO -     return _ConnectionRecord(self)
[2023-03-10 01:17:51,807] {subprocess.py:92} INFO -   File "/home/***/.local/lib/python3.7/site-packages/sqlalchemy/pool/base.py", line 362, in __init__
[2023-03-10 01:17:51,809] {subprocess.py:92} INFO -     self.__connect(first_connect_check=True)
[2023-03-10 01:17:51,810] {subprocess.py:92} INFO -   File "/home/***/.local/lib/python3.7/site-packages/sqlalchemy/pool/base.py", line 605, in __connect
[2023-03-10 01:17:51,811] {subprocess.py:92} INFO -     pool.logger.debug("Error on connect(): %s", e)
[2023-03-10 01:17:51,812] {subprocess.py:92} INFO -   File "/home/***/.local/lib/python3.7/site-packages/sqlalchemy/util/langhelpers.py", line 72, in __exit__
[2023-03-10 01:17:51,813] {subprocess.py:92} INFO -     with_traceback=exc_tb,
[2023-03-10 01:17:51,814] {subprocess.py:92} INFO -   File "/home/***/.local/lib/python3.7/site-packages/sqlalchemy/util/compat.py", line 211, in raise_
[2023-03-10 01:17:51,814] {subprocess.py:92} INFO -     raise exception
[2023-03-10 01:17:51,815] {subprocess.py:92} INFO -   File "/home/***/.local/lib/python3.7/site-packages/sqlalchemy/pool/base.py", line 599, in __connect
[2023-03-10 01:17:51,816] {subprocess.py:92} INFO -     connection = pool._invoke_creator(self)
[2023-03-10 01:17:51,817] {subprocess.py:92} INFO -   File "/home/***/.local/lib/python3.7/site-packages/sqlalchemy/engine/create.py", line 578, in connect
[2023-03-10 01:17:51,818] {subprocess.py:92} INFO -     return dialect.connect(*cargs, **cparams)
[2023-03-10 01:17:51,819] {subprocess.py:92} INFO -   File "/home/***/.local/lib/python3.7/site-packages/sqlalchemy/engine/default.py", line 583, in connect
[2023-03-10 01:17:51,820] {subprocess.py:92} INFO -     return self.dbapi.connect(*cargs, **cparams)
[2023-03-10 01:17:51,826] {subprocess.py:92} INFO -   File "/home/***/.local/lib/python3.7/site-packages/pymysql/connections.py", line 353, in __init__
[2023-03-10 01:17:51,827] {subprocess.py:92} INFO -     self.connect()
[2023-03-10 01:17:51,827] {subprocess.py:92} INFO -   File "/home/***/.local/lib/python3.7/site-packages/pymysql/connections.py", line 664, in connect
[2023-03-10 01:17:51,828] {subprocess.py:92} INFO -     raise exc
[2023-03-10 01:17:51,829] {subprocess.py:92} INFO - sqlalchemy.exc.OperationalError: (pymysql.err.OperationalError) (2003, "Can't connect to MySQL server on '127.0.0.1' ([Errno 111] Connection refused)")
[2023-03-10 01:17:51,830] {subprocess.py:92} INFO - (Background on this error at: http://sqlalche.me/e/14/e3q8)
[2023-03-10 01:17:51,832] {subprocess.py:96} INFO - Command exited with return code 1
[2023-03-10 01:17:51,843] {taskinstance.py:1889} ERROR - Task failed with exception
Traceback (most recent call last):
  File "/home/airflow/.local/lib/python3.7/site-packages/airflow/operators/bash.py", line 195, in execute
    f'Bash command failed. The command returned a non-zero exit code {result.exit_code}.'
airflow.exceptions.AirflowException: Bash command failed. The command returned a non-zero exit code 1.
[2023-03-10 01:17:51,846] {taskinstance.py:1400} INFO - Marking task as FAILED. dag_id=pipeline_bash_operator, task_id=run_script_transform, execution_date=20230310T011704, start_date=20230310T011724, end_date=20230310T011751
[2023-03-10 01:17:51,856] {standard_task_runner.py:97} ERROR - Failed to execute job 75 for task run_script_transform (Bash command failed. The command returned a non-zero exit code 1.; 1130)
[2023-03-10 01:17:51,904] {local_task_job.py:156} INFO - Task exited with return code 1
[2023-03-10 01:17:51,920] {local_task_job.py:273} INFO - 0 downstream tasks scheduled from follow-on schedule check
