[2023-03-10 00:56:44,998] {taskinstance.py:1159} INFO - Dependencies all met for <TaskInstance: pipeline_bash_operator.run_script_transform manual__2023-03-10T00:56:25.914951+00:00 [queued]>
[2023-03-10 00:56:45,005] {taskinstance.py:1159} INFO - Dependencies all met for <TaskInstance: pipeline_bash_operator.run_script_transform manual__2023-03-10T00:56:25.914951+00:00 [queued]>
[2023-03-10 00:56:45,006] {taskinstance.py:1356} INFO - 
--------------------------------------------------------------------------------
[2023-03-10 00:56:45,007] {taskinstance.py:1357} INFO - Starting attempt 1 of 1
[2023-03-10 00:56:45,008] {taskinstance.py:1358} INFO - 
--------------------------------------------------------------------------------
[2023-03-10 00:56:45,016] {taskinstance.py:1377} INFO - Executing <Task(BashOperator): run_script_transform> on 2023-03-10 00:56:25.914951+00:00
[2023-03-10 00:56:45,020] {standard_task_runner.py:52} INFO - Started process 618 to run task
[2023-03-10 00:56:45,022] {standard_task_runner.py:79} INFO - Running: ['***', 'tasks', 'run', 'pipeline_bash_operator', 'run_script_transform', 'manual__2023-03-10T00:56:25.914951+00:00', '--job-id', '67', '--raw', '--subdir', 'DAGS_FOLDER/pipeline_bash_operator.py', '--cfg-path', '/tmp/tmpqf_euu_a', '--error-file', '/tmp/tmpaf97j9mo']
[2023-03-10 00:56:45,024] {standard_task_runner.py:80} INFO - Job 67: Subtask run_script_transform
[2023-03-10 00:56:45,073] {task_command.py:369} INFO - Running <TaskInstance: pipeline_bash_operator.run_script_transform manual__2023-03-10T00:56:25.914951+00:00 [running]> on host 477ef5e408be
[2023-03-10 00:56:45,119] {taskinstance.py:1571} INFO - Exporting the following env vars:
AIRFLOW_CTX_DAG_OWNER=Americo
AIRFLOW_CTX_DAG_ID=pipeline_bash_operator
AIRFLOW_CTX_TASK_ID=run_script_transform
AIRFLOW_CTX_EXECUTION_DATE=2023-03-10T00:56:25.914951+00:00
AIRFLOW_CTX_TRY_NUMBER=1
AIRFLOW_CTX_DAG_RUN_ID=manual__2023-03-10T00:56:25.914951+00:00
[2023-03-10 00:56:45,120] {subprocess.py:62} INFO - Tmp dir root location: 
 /tmp
[2023-03-10 00:56:45,122] {subprocess.py:74} INFO - Running command: ['bash', '-c', 'python /opt/***/dags/Proyecto/transform.py']
[2023-03-10 00:56:45,131] {subprocess.py:85} INFO - Output:
[2023-03-10 00:57:12,358] {subprocess.py:92} INFO - ingest loaded
[2023-03-10 00:57:12,361] {subprocess.py:92} INFO - loaded adsl landing
[2023-03-10 00:57:12,365] {subprocess.py:92} INFO - transform loaded
[2023-03-10 00:57:12,367] {subprocess.py:92} INFO - loaded adsl gold
[2023-03-10 00:57:12,383] {subprocess.py:92} INFO - Traceback (most recent call last):
[2023-03-10 00:57:12,384] {subprocess.py:92} INFO -   File "/home/***/.local/lib/python3.7/site-packages/pymysql/connections.py", line 614, in connect
[2023-03-10 00:57:12,385] {subprocess.py:92} INFO -     (self.host, self.port), self.connect_timeout, **kwargs
[2023-03-10 00:57:12,387] {subprocess.py:92} INFO -   File "/usr/local/lib/python3.7/socket.py", line 728, in create_connection
[2023-03-10 00:57:12,388] {subprocess.py:92} INFO -     raise err
[2023-03-10 00:57:12,389] {subprocess.py:92} INFO -   File "/usr/local/lib/python3.7/socket.py", line 716, in create_connection
[2023-03-10 00:57:12,390] {subprocess.py:92} INFO -     sock.connect(sa)
[2023-03-10 00:57:12,392] {subprocess.py:92} INFO - ConnectionRefusedError: [Errno 111] Connection refused
[2023-03-10 00:57:12,393] {subprocess.py:92} INFO - 
[2023-03-10 00:57:12,394] {subprocess.py:92} INFO - During handling of the above exception, another exception occurred:
[2023-03-10 00:57:12,395] {subprocess.py:92} INFO - 
[2023-03-10 00:57:12,396] {subprocess.py:92} INFO - Traceback (most recent call last):
[2023-03-10 00:57:12,397] {subprocess.py:92} INFO -   File "/home/***/.local/lib/python3.7/site-packages/sqlalchemy/engine/base.py", line 3141, in _wrap_pool_connect
[2023-03-10 00:57:12,399] {subprocess.py:92} INFO -     return fn()
[2023-03-10 00:57:12,400] {subprocess.py:92} INFO -   File "/home/***/.local/lib/python3.7/site-packages/sqlalchemy/pool/base.py", line 301, in connect
[2023-03-10 00:57:12,400] {subprocess.py:92} INFO -     return _ConnectionFairy._checkout(self)
[2023-03-10 00:57:12,402] {subprocess.py:92} INFO -   File "/home/***/.local/lib/python3.7/site-packages/sqlalchemy/pool/base.py", line 755, in _checkout
[2023-03-10 00:57:12,403] {subprocess.py:92} INFO -     fairy = _ConnectionRecord.checkout(pool)
[2023-03-10 00:57:12,403] {subprocess.py:92} INFO -   File "/home/***/.local/lib/python3.7/site-packages/sqlalchemy/pool/base.py", line 419, in checkout
[2023-03-10 00:57:12,404] {subprocess.py:92} INFO -     rec = pool._do_get()
[2023-03-10 00:57:12,405] {subprocess.py:92} INFO -   File "/home/***/.local/lib/python3.7/site-packages/sqlalchemy/pool/impl.py", line 145, in _do_get
[2023-03-10 00:57:12,406] {subprocess.py:92} INFO -     self._dec_overflow()
[2023-03-10 00:57:12,407] {subprocess.py:92} INFO -   File "/home/***/.local/lib/python3.7/site-packages/sqlalchemy/util/langhelpers.py", line 72, in __exit__
[2023-03-10 00:57:12,408] {subprocess.py:92} INFO -     with_traceback=exc_tb,
[2023-03-10 00:57:12,409] {subprocess.py:92} INFO -   File "/home/***/.local/lib/python3.7/site-packages/sqlalchemy/util/compat.py", line 211, in raise_
[2023-03-10 00:57:12,410] {subprocess.py:92} INFO -     raise exception
[2023-03-10 00:57:12,410] {subprocess.py:92} INFO -   File "/home/***/.local/lib/python3.7/site-packages/sqlalchemy/pool/impl.py", line 142, in _do_get
[2023-03-10 00:57:12,411] {subprocess.py:92} INFO -     return self._create_connection()
[2023-03-10 00:57:12,412] {subprocess.py:92} INFO -   File "/home/***/.local/lib/python3.7/site-packages/sqlalchemy/pool/base.py", line 247, in _create_connection
[2023-03-10 00:57:12,412] {subprocess.py:92} INFO -     return _ConnectionRecord(self)
[2023-03-10 00:57:12,413] {subprocess.py:92} INFO -   File "/home/***/.local/lib/python3.7/site-packages/sqlalchemy/pool/base.py", line 362, in __init__
[2023-03-10 00:57:12,414] {subprocess.py:92} INFO -     self.__connect(first_connect_check=True)
[2023-03-10 00:57:12,415] {subprocess.py:92} INFO -   File "/home/***/.local/lib/python3.7/site-packages/sqlalchemy/pool/base.py", line 605, in __connect
[2023-03-10 00:57:12,415] {subprocess.py:92} INFO -     pool.logger.debug("Error on connect(): %s", e)
[2023-03-10 00:57:12,416] {subprocess.py:92} INFO -   File "/home/***/.local/lib/python3.7/site-packages/sqlalchemy/util/langhelpers.py", line 72, in __exit__
[2023-03-10 00:57:12,417] {subprocess.py:92} INFO -     with_traceback=exc_tb,
[2023-03-10 00:57:12,417] {subprocess.py:92} INFO -   File "/home/***/.local/lib/python3.7/site-packages/sqlalchemy/util/compat.py", line 211, in raise_
[2023-03-10 00:57:12,418] {subprocess.py:92} INFO -     raise exception
[2023-03-10 00:57:12,419] {subprocess.py:92} INFO -   File "/home/***/.local/lib/python3.7/site-packages/sqlalchemy/pool/base.py", line 599, in __connect
[2023-03-10 00:57:12,420] {subprocess.py:92} INFO -     connection = pool._invoke_creator(self)
[2023-03-10 00:57:12,420] {subprocess.py:92} INFO -   File "/home/***/.local/lib/python3.7/site-packages/sqlalchemy/engine/create.py", line 578, in connect
[2023-03-10 00:57:12,421] {subprocess.py:92} INFO -     return dialect.connect(*cargs, **cparams)
[2023-03-10 00:57:12,422] {subprocess.py:92} INFO -   File "/home/***/.local/lib/python3.7/site-packages/sqlalchemy/engine/default.py", line 583, in connect
[2023-03-10 00:57:12,422] {subprocess.py:92} INFO -     return self.dbapi.connect(*cargs, **cparams)
[2023-03-10 00:57:12,423] {subprocess.py:92} INFO -   File "/home/***/.local/lib/python3.7/site-packages/pymysql/connections.py", line 353, in __init__
[2023-03-10 00:57:12,424] {subprocess.py:92} INFO -     self.connect()
[2023-03-10 00:57:12,425] {subprocess.py:92} INFO -   File "/home/***/.local/lib/python3.7/site-packages/pymysql/connections.py", line 664, in connect
[2023-03-10 00:57:12,426] {subprocess.py:92} INFO -     raise exc
[2023-03-10 00:57:12,427] {subprocess.py:92} INFO - pymysql.err.OperationalError: (2003, "Can't connect to MySQL server on '127.0.0.1' ([Errno 111] Connection refused)")
[2023-03-10 00:57:12,428] {subprocess.py:92} INFO - 
[2023-03-10 00:57:12,429] {subprocess.py:92} INFO - The above exception was the direct cause of the following exception:
[2023-03-10 00:57:12,430] {subprocess.py:92} INFO - 
[2023-03-10 00:57:12,431] {subprocess.py:92} INFO - Traceback (most recent call last):
[2023-03-10 00:57:12,431] {subprocess.py:92} INFO -   File "/opt/***/dags/Proyecto/transform.py", line 32, in <module>
[2023-03-10 00:57:12,432] {subprocess.py:92} INFO -     load.load_mysql(df_enunciado1, "enunciado1")
[2023-03-10 00:57:12,433] {subprocess.py:92} INFO -   File "/opt/***/dags/Proyecto/process/load.py", line 28, in load_mysql
[2023-03-10 00:57:12,434] {subprocess.py:92} INFO -     u.df_to_mysql(df, u.mysql_engine(), db_tbl_name)
[2023-03-10 00:57:12,434] {subprocess.py:92} INFO -   File "/opt/***/dags/Proyecto/process/util/utils.py", line 59, in df_to_mysql
[2023-03-10 00:57:12,435] {subprocess.py:92} INFO -     df.to_sql(tbl_name, engine, if_exists='replace')
[2023-03-10 00:57:12,436] {subprocess.py:92} INFO -   File "/home/***/.local/lib/python3.7/site-packages/pandas/core/generic.py", line 2882, in to_sql
[2023-03-10 00:57:12,438] {subprocess.py:92} INFO -     method=method,
[2023-03-10 00:57:12,439] {subprocess.py:92} INFO -   File "/home/***/.local/lib/python3.7/site-packages/pandas/io/sql.py", line 728, in to_sql
[2023-03-10 00:57:12,440] {subprocess.py:92} INFO -     **engine_kwargs,
[2023-03-10 00:57:12,441] {subprocess.py:92} INFO -   File "/home/***/.local/lib/python3.7/site-packages/pandas/io/sql.py", line 1758, in to_sql
[2023-03-10 00:57:12,442] {subprocess.py:92} INFO -     dtype=dtype,
[2023-03-10 00:57:12,443] {subprocess.py:92} INFO -   File "/home/***/.local/lib/python3.7/site-packages/pandas/io/sql.py", line 1650, in prep_table
[2023-03-10 00:57:12,444] {subprocess.py:92} INFO -     table.create()
[2023-03-10 00:57:12,445] {subprocess.py:92} INFO -   File "/home/***/.local/lib/python3.7/site-packages/pandas/io/sql.py", line 856, in create
[2023-03-10 00:57:12,446] {subprocess.py:92} INFO -     if self.exists():
[2023-03-10 00:57:12,447] {subprocess.py:92} INFO -   File "/home/***/.local/lib/python3.7/site-packages/pandas/io/sql.py", line 840, in exists
[2023-03-10 00:57:12,447] {subprocess.py:92} INFO -     return self.pd_sql.has_table(self.name, self.schema)
[2023-03-10 00:57:12,448] {subprocess.py:92} INFO -   File "/home/***/.local/lib/python3.7/site-packages/pandas/io/sql.py", line 1783, in has_table
[2023-03-10 00:57:12,449] {subprocess.py:92} INFO -     insp = sa.inspect(self.connectable)
[2023-03-10 00:57:12,450] {subprocess.py:92} INFO -   File "/home/***/.local/lib/python3.7/site-packages/sqlalchemy/inspection.py", line 64, in inspect
[2023-03-10 00:57:12,451] {subprocess.py:92} INFO -     ret = reg(subject)
[2023-03-10 00:57:12,452] {subprocess.py:92} INFO -   File "/home/***/.local/lib/python3.7/site-packages/sqlalchemy/engine/reflection.py", line 182, in _engine_insp
[2023-03-10 00:57:12,452] {subprocess.py:92} INFO -     return Inspector._construct(Inspector._init_engine, bind)
[2023-03-10 00:57:12,453] {subprocess.py:92} INFO -   File "/home/***/.local/lib/python3.7/site-packages/sqlalchemy/engine/reflection.py", line 117, in _construct
[2023-03-10 00:57:12,454] {subprocess.py:92} INFO -     init(self, bind)
[2023-03-10 00:57:12,454] {subprocess.py:92} INFO -   File "/home/***/.local/lib/python3.7/site-packages/sqlalchemy/engine/reflection.py", line 128, in _init_engine
[2023-03-10 00:57:12,455] {subprocess.py:92} INFO -     engine.connect().close()
[2023-03-10 00:57:12,456] {subprocess.py:92} INFO -   File "/home/***/.local/lib/python3.7/site-packages/sqlalchemy/engine/base.py", line 3095, in connect
[2023-03-10 00:57:12,457] {subprocess.py:92} INFO -     return self._connection_cls(self, close_with_result=close_with_result)
[2023-03-10 00:57:12,458] {subprocess.py:92} INFO -   File "/home/***/.local/lib/python3.7/site-packages/sqlalchemy/engine/base.py", line 91, in __init__
[2023-03-10 00:57:12,459] {subprocess.py:92} INFO -     else engine.raw_connection()
[2023-03-10 00:57:12,459] {subprocess.py:92} INFO -   File "/home/***/.local/lib/python3.7/site-packages/sqlalchemy/engine/base.py", line 3174, in raw_connection
[2023-03-10 00:57:12,460] {subprocess.py:92} INFO -     return self._wrap_pool_connect(self.pool.connect, _connection)
[2023-03-10 00:57:12,461] {subprocess.py:92} INFO -   File "/home/***/.local/lib/python3.7/site-packages/sqlalchemy/engine/base.py", line 3145, in _wrap_pool_connect
[2023-03-10 00:57:12,461] {subprocess.py:92} INFO -     e, dialect, self
[2023-03-10 00:57:12,462] {subprocess.py:92} INFO -   File "/home/***/.local/lib/python3.7/site-packages/sqlalchemy/engine/base.py", line 2004, in _handle_dbapi_exception_noconnection
[2023-03-10 00:57:12,463] {subprocess.py:92} INFO -     sqlalchemy_exception, with_traceback=exc_info[2], from_=e
[2023-03-10 00:57:12,463] {subprocess.py:92} INFO -   File "/home/***/.local/lib/python3.7/site-packages/sqlalchemy/util/compat.py", line 211, in raise_
[2023-03-10 00:57:12,464] {subprocess.py:92} INFO -     raise exception
[2023-03-10 00:57:12,465] {subprocess.py:92} INFO -   File "/home/***/.local/lib/python3.7/site-packages/sqlalchemy/engine/base.py", line 3141, in _wrap_pool_connect
[2023-03-10 00:57:12,465] {subprocess.py:92} INFO -     return fn()
[2023-03-10 00:57:12,466] {subprocess.py:92} INFO -   File "/home/***/.local/lib/python3.7/site-packages/sqlalchemy/pool/base.py", line 301, in connect
[2023-03-10 00:57:12,466] {subprocess.py:92} INFO -     return _ConnectionFairy._checkout(self)
[2023-03-10 00:57:12,467] {subprocess.py:92} INFO -   File "/home/***/.local/lib/python3.7/site-packages/sqlalchemy/pool/base.py", line 755, in _checkout
[2023-03-10 00:57:12,468] {subprocess.py:92} INFO -     fairy = _ConnectionRecord.checkout(pool)
[2023-03-10 00:57:12,468] {subprocess.py:92} INFO -   File "/home/***/.local/lib/python3.7/site-packages/sqlalchemy/pool/base.py", line 419, in checkout
[2023-03-10 00:57:12,469] {subprocess.py:92} INFO -     rec = pool._do_get()
[2023-03-10 00:57:12,469] {subprocess.py:92} INFO -   File "/home/***/.local/lib/python3.7/site-packages/sqlalchemy/pool/impl.py", line 145, in _do_get
[2023-03-10 00:57:12,470] {subprocess.py:92} INFO -     self._dec_overflow()
[2023-03-10 00:57:12,470] {subprocess.py:92} INFO -   File "/home/***/.local/lib/python3.7/site-packages/sqlalchemy/util/langhelpers.py", line 72, in __exit__
[2023-03-10 00:57:12,471] {subprocess.py:92} INFO -     with_traceback=exc_tb,
[2023-03-10 00:57:12,472] {subprocess.py:92} INFO -   File "/home/***/.local/lib/python3.7/site-packages/sqlalchemy/util/compat.py", line 211, in raise_
[2023-03-10 00:57:12,473] {subprocess.py:92} INFO -     raise exception
[2023-03-10 00:57:12,473] {subprocess.py:92} INFO -   File "/home/***/.local/lib/python3.7/site-packages/sqlalchemy/pool/impl.py", line 142, in _do_get
[2023-03-10 00:57:12,474] {subprocess.py:92} INFO -     return self._create_connection()
[2023-03-10 00:57:12,475] {subprocess.py:92} INFO -   File "/home/***/.local/lib/python3.7/site-packages/sqlalchemy/pool/base.py", line 247, in _create_connection
[2023-03-10 00:57:12,475] {subprocess.py:92} INFO -     return _ConnectionRecord(self)
[2023-03-10 00:57:12,476] {subprocess.py:92} INFO -   File "/home/***/.local/lib/python3.7/site-packages/sqlalchemy/pool/base.py", line 362, in __init__
[2023-03-10 00:57:12,477] {subprocess.py:92} INFO -     self.__connect(first_connect_check=True)
[2023-03-10 00:57:12,478] {subprocess.py:92} INFO -   File "/home/***/.local/lib/python3.7/site-packages/sqlalchemy/pool/base.py", line 605, in __connect
[2023-03-10 00:57:12,478] {subprocess.py:92} INFO -     pool.logger.debug("Error on connect(): %s", e)
[2023-03-10 00:57:12,479] {subprocess.py:92} INFO -   File "/home/***/.local/lib/python3.7/site-packages/sqlalchemy/util/langhelpers.py", line 72, in __exit__
[2023-03-10 00:57:12,480] {subprocess.py:92} INFO -     with_traceback=exc_tb,
[2023-03-10 00:57:12,480] {subprocess.py:92} INFO -   File "/home/***/.local/lib/python3.7/site-packages/sqlalchemy/util/compat.py", line 211, in raise_
[2023-03-10 00:57:12,481] {subprocess.py:92} INFO -     raise exception
[2023-03-10 00:57:12,483] {subprocess.py:92} INFO -   File "/home/***/.local/lib/python3.7/site-packages/sqlalchemy/pool/base.py", line 599, in __connect
[2023-03-10 00:57:12,483] {subprocess.py:92} INFO -     connection = pool._invoke_creator(self)
[2023-03-10 00:57:12,485] {subprocess.py:92} INFO -   File "/home/***/.local/lib/python3.7/site-packages/sqlalchemy/engine/create.py", line 578, in connect
[2023-03-10 00:57:12,486] {subprocess.py:92} INFO -     return dialect.connect(*cargs, **cparams)
[2023-03-10 00:57:12,486] {subprocess.py:92} INFO -   File "/home/***/.local/lib/python3.7/site-packages/sqlalchemy/engine/default.py", line 583, in connect
[2023-03-10 00:57:12,487] {subprocess.py:92} INFO -     return self.dbapi.connect(*cargs, **cparams)
[2023-03-10 00:57:12,488] {subprocess.py:92} INFO -   File "/home/***/.local/lib/python3.7/site-packages/pymysql/connections.py", line 353, in __init__
[2023-03-10 00:57:12,489] {subprocess.py:92} INFO -     self.connect()
[2023-03-10 00:57:12,489] {subprocess.py:92} INFO -   File "/home/***/.local/lib/python3.7/site-packages/pymysql/connections.py", line 664, in connect
[2023-03-10 00:57:12,490] {subprocess.py:92} INFO -     raise exc
[2023-03-10 00:57:12,491] {subprocess.py:92} INFO - sqlalchemy.exc.OperationalError: (pymysql.err.OperationalError) (2003, "Can't connect to MySQL server on '127.0.0.1' ([Errno 111] Connection refused)")
[2023-03-10 00:57:12,492] {subprocess.py:92} INFO - (Background on this error at: http://sqlalche.me/e/14/e3q8)
[2023-03-10 00:57:12,532] {subprocess.py:96} INFO - Command exited with return code 1
[2023-03-10 00:57:12,544] {taskinstance.py:1889} ERROR - Task failed with exception
Traceback (most recent call last):
  File "/home/airflow/.local/lib/python3.7/site-packages/airflow/operators/bash.py", line 195, in execute
    f'Bash command failed. The command returned a non-zero exit code {result.exit_code}.'
airflow.exceptions.AirflowException: Bash command failed. The command returned a non-zero exit code 1.
[2023-03-10 00:57:12,548] {taskinstance.py:1400} INFO - Marking task as FAILED. dag_id=pipeline_bash_operator, task_id=run_script_transform, execution_date=20230310T005625, start_date=20230310T005644, end_date=20230310T005712
[2023-03-10 00:57:12,557] {standard_task_runner.py:97} ERROR - Failed to execute job 67 for task run_script_transform (Bash command failed. The command returned a non-zero exit code 1.; 618)
[2023-03-10 00:57:12,600] {local_task_job.py:156} INFO - Task exited with return code 1
[2023-03-10 00:57:12,617] {local_task_job.py:273} INFO - 0 downstream tasks scheduled from follow-on schedule check
