[2023-03-10 01:43:07,499] {taskinstance.py:1159} INFO - Dependencies all met for <TaskInstance: pipeline_bash_operator.run_script_transform manual__2023-03-10T01:42:46.708286+00:00 [queued]>
[2023-03-10 01:43:07,506] {taskinstance.py:1159} INFO - Dependencies all met for <TaskInstance: pipeline_bash_operator.run_script_transform manual__2023-03-10T01:42:46.708286+00:00 [queued]>
[2023-03-10 01:43:07,507] {taskinstance.py:1356} INFO - 
--------------------------------------------------------------------------------
[2023-03-10 01:43:07,508] {taskinstance.py:1357} INFO - Starting attempt 1 of 1
[2023-03-10 01:43:07,509] {taskinstance.py:1358} INFO - 
--------------------------------------------------------------------------------
[2023-03-10 01:43:07,518] {taskinstance.py:1377} INFO - Executing <Task(BashOperator): run_script_transform> on 2023-03-10 01:42:46.708286+00:00
[2023-03-10 01:43:07,522] {standard_task_runner.py:52} INFO - Started process 1669 to run task
[2023-03-10 01:43:07,524] {standard_task_runner.py:79} INFO - Running: ['***', 'tasks', 'run', 'pipeline_bash_operator', 'run_script_transform', 'manual__2023-03-10T01:42:46.708286+00:00', '--job-id', '77', '--raw', '--subdir', 'DAGS_FOLDER/pipeline_bash_operator.py', '--cfg-path', '/tmp/tmp34brqxb3', '--error-file', '/tmp/tmpbg70pa20']
[2023-03-10 01:43:07,526] {standard_task_runner.py:80} INFO - Job 77: Subtask run_script_transform
[2023-03-10 01:43:07,569] {task_command.py:369} INFO - Running <TaskInstance: pipeline_bash_operator.run_script_transform manual__2023-03-10T01:42:46.708286+00:00 [running]> on host 477ef5e408be
[2023-03-10 01:43:07,620] {taskinstance.py:1571} INFO - Exporting the following env vars:
AIRFLOW_CTX_DAG_OWNER=Americo
AIRFLOW_CTX_DAG_ID=pipeline_bash_operator
AIRFLOW_CTX_TASK_ID=run_script_transform
AIRFLOW_CTX_EXECUTION_DATE=2023-03-10T01:42:46.708286+00:00
AIRFLOW_CTX_TRY_NUMBER=1
AIRFLOW_CTX_DAG_RUN_ID=manual__2023-03-10T01:42:46.708286+00:00
[2023-03-10 01:43:07,623] {subprocess.py:62} INFO - Tmp dir root location: 
 /tmp
[2023-03-10 01:43:07,625] {subprocess.py:74} INFO - Running command: ['bash', '-c', 'python /opt/***/dags/Proyecto/transform.py']
[2023-03-10 01:43:07,634] {subprocess.py:85} INFO - Output:
[2023-03-10 01:43:37,901] {subprocess.py:92} INFO - ingest loaded
[2023-03-10 01:43:37,902] {subprocess.py:92} INFO - loaded adsl landing
[2023-03-10 01:43:37,904] {subprocess.py:92} INFO - transform loaded
[2023-03-10 01:43:37,905] {subprocess.py:92} INFO - loaded adsl gold
[2023-03-10 01:43:37,906] {subprocess.py:92} INFO - Traceback (most recent call last):
[2023-03-10 01:43:37,907] {subprocess.py:92} INFO -   File "/opt/***/dags/Proyecto/transform.py", line 33, in <module>
[2023-03-10 01:43:37,908] {subprocess.py:92} INFO -     u.create_mysql_tbl_schema(df_enunciado1, u.mysql_conn(u.mysql_engine()), 'retail', "enunciado1")
[2023-03-10 01:43:37,909] {subprocess.py:92} INFO -   File "/opt/***/dags/Proyecto/process/util/utils.py", line 51, in create_mysql_tbl_schema
[2023-03-10 01:43:37,910] {subprocess.py:92} INFO -     cur.execute(sql)
[2023-03-10 01:43:37,911] {subprocess.py:92} INFO -   File "/home/***/.local/lib/python3.7/site-packages/pymysql/cursors.py", line 148, in execute
[2023-03-10 01:43:37,913] {subprocess.py:92} INFO -     result = self._query(query)
[2023-03-10 01:43:37,913] {subprocess.py:92} INFO -   File "/home/***/.local/lib/python3.7/site-packages/pymysql/cursors.py", line 310, in _query
[2023-03-10 01:43:37,914] {subprocess.py:92} INFO -     conn.query(q)
[2023-03-10 01:43:37,915] {subprocess.py:92} INFO -   File "/home/***/.local/lib/python3.7/site-packages/pymysql/connections.py", line 548, in query
[2023-03-10 01:43:37,916] {subprocess.py:92} INFO -     self._affected_rows = self._read_query_result(unbuffered=unbuffered)
[2023-03-10 01:43:37,917] {subprocess.py:92} INFO -   File "/home/***/.local/lib/python3.7/site-packages/pymysql/connections.py", line 775, in _read_query_result
[2023-03-10 01:43:37,918] {subprocess.py:92} INFO -     result.read()
[2023-03-10 01:43:37,919] {subprocess.py:92} INFO -   File "/home/***/.local/lib/python3.7/site-packages/pymysql/connections.py", line 1156, in read
[2023-03-10 01:43:37,921] {subprocess.py:92} INFO -     first_packet = self.connection._read_packet()
[2023-03-10 01:43:37,922] {subprocess.py:92} INFO -   File "/home/***/.local/lib/python3.7/site-packages/pymysql/connections.py", line 725, in _read_packet
[2023-03-10 01:43:37,923] {subprocess.py:92} INFO -     packet.raise_for_error()
[2023-03-10 01:43:37,924] {subprocess.py:92} INFO -   File "/home/***/.local/lib/python3.7/site-packages/pymysql/protocol.py", line 221, in raise_for_error
[2023-03-10 01:43:37,925] {subprocess.py:92} INFO -     err.raise_mysql_exception(self._data)
[2023-03-10 01:43:37,926] {subprocess.py:92} INFO -   File "/home/***/.local/lib/python3.7/site-packages/pymysql/err.py", line 143, in raise_mysql_exception
[2023-03-10 01:43:37,927] {subprocess.py:92} INFO -     raise errorclass(errno, errval)
[2023-03-10 01:43:37,928] {subprocess.py:92} INFO - pymysql.err.ProgrammingError: (1064, "You have an error in your SQL syntax; check the manual that corresponds to your MySQL server version for the right syntax to use near 'CREATE TABLE IF NOT EXISTS enunciado1 (pi_db_uid INT AUTO_INCREMENT PRIMARY KEY ' at line 1")
[2023-03-10 01:43:37,999] {subprocess.py:96} INFO - Command exited with return code 1
[2023-03-10 01:43:38,011] {taskinstance.py:1889} ERROR - Task failed with exception
Traceback (most recent call last):
  File "/home/airflow/.local/lib/python3.7/site-packages/airflow/operators/bash.py", line 195, in execute
    f'Bash command failed. The command returned a non-zero exit code {result.exit_code}.'
airflow.exceptions.AirflowException: Bash command failed. The command returned a non-zero exit code 1.
[2023-03-10 01:43:38,014] {taskinstance.py:1400} INFO - Marking task as FAILED. dag_id=pipeline_bash_operator, task_id=run_script_transform, execution_date=20230310T014246, start_date=20230310T014307, end_date=20230310T014338
[2023-03-10 01:43:38,024] {standard_task_runner.py:97} ERROR - Failed to execute job 77 for task run_script_transform (Bash command failed. The command returned a non-zero exit code 1.; 1669)
[2023-03-10 01:43:38,047] {local_task_job.py:156} INFO - Task exited with return code 1
[2023-03-10 01:43:38,064] {local_task_job.py:273} INFO - 0 downstream tasks scheduled from follow-on schedule check
