[2023-03-10 01:03:21,276] {taskinstance.py:1159} INFO - Dependencies all met for <TaskInstance: pipeline_bash_operator.run_script_transform manual__2023-03-10T01:03:00.990306+00:00 [queued]>
[2023-03-10 01:03:21,283] {taskinstance.py:1159} INFO - Dependencies all met for <TaskInstance: pipeline_bash_operator.run_script_transform manual__2023-03-10T01:03:00.990306+00:00 [queued]>
[2023-03-10 01:03:21,284] {taskinstance.py:1356} INFO - 
--------------------------------------------------------------------------------
[2023-03-10 01:03:21,285] {taskinstance.py:1357} INFO - Starting attempt 1 of 1
[2023-03-10 01:03:21,286] {taskinstance.py:1358} INFO - 
--------------------------------------------------------------------------------
[2023-03-10 01:03:21,295] {taskinstance.py:1377} INFO - Executing <Task(BashOperator): run_script_transform> on 2023-03-10 01:03:00.990306+00:00
[2023-03-10 01:03:21,298] {standard_task_runner.py:52} INFO - Started process 796 to run task
[2023-03-10 01:03:21,301] {standard_task_runner.py:79} INFO - Running: ['***', 'tasks', 'run', 'pipeline_bash_operator', 'run_script_transform', 'manual__2023-03-10T01:03:00.990306+00:00', '--job-id', '69', '--raw', '--subdir', 'DAGS_FOLDER/pipeline_bash_operator.py', '--cfg-path', '/tmp/tmpdmzeqeks', '--error-file', '/tmp/tmp9dixtq9l']
[2023-03-10 01:03:21,303] {standard_task_runner.py:80} INFO - Job 69: Subtask run_script_transform
[2023-03-10 01:03:21,338] {task_command.py:369} INFO - Running <TaskInstance: pipeline_bash_operator.run_script_transform manual__2023-03-10T01:03:00.990306+00:00 [running]> on host 477ef5e408be
[2023-03-10 01:03:21,382] {taskinstance.py:1571} INFO - Exporting the following env vars:
AIRFLOW_CTX_DAG_OWNER=Americo
AIRFLOW_CTX_DAG_ID=pipeline_bash_operator
AIRFLOW_CTX_TASK_ID=run_script_transform
AIRFLOW_CTX_EXECUTION_DATE=2023-03-10T01:03:00.990306+00:00
AIRFLOW_CTX_TRY_NUMBER=1
AIRFLOW_CTX_DAG_RUN_ID=manual__2023-03-10T01:03:00.990306+00:00
[2023-03-10 01:03:21,383] {subprocess.py:62} INFO - Tmp dir root location: 
 /tmp
[2023-03-10 01:03:21,384] {subprocess.py:74} INFO - Running command: ['bash', '-c', 'python /opt/***/dags/Proyecto/transform.py']
[2023-03-10 01:03:21,391] {subprocess.py:85} INFO - Output:
[2023-03-10 01:03:50,039] {subprocess.py:92} INFO - ingest loaded
[2023-03-10 01:03:50,041] {subprocess.py:92} INFO - loaded adsl landing
[2023-03-10 01:03:50,043] {subprocess.py:92} INFO - transform loaded
[2023-03-10 01:03:50,045] {subprocess.py:92} INFO - loaded adsl gold
[2023-03-10 01:03:50,058] {subprocess.py:92} INFO - Traceback (most recent call last):
[2023-03-10 01:03:50,059] {subprocess.py:92} INFO -   File "/home/***/.local/lib/python3.7/site-packages/pymysql/connections.py", line 614, in connect
[2023-03-10 01:03:50,062] {subprocess.py:92} INFO -     (self.host, self.port), self.connect_timeout, **kwargs
[2023-03-10 01:03:50,063] {subprocess.py:92} INFO -   File "/usr/local/lib/python3.7/socket.py", line 728, in create_connection
[2023-03-10 01:03:50,065] {subprocess.py:92} INFO -     raise err
[2023-03-10 01:03:50,066] {subprocess.py:92} INFO -   File "/usr/local/lib/python3.7/socket.py", line 716, in create_connection
[2023-03-10 01:03:50,067] {subprocess.py:92} INFO -     sock.connect(sa)
[2023-03-10 01:03:50,068] {subprocess.py:92} INFO - ConnectionRefusedError: [Errno 111] Connection refused
[2023-03-10 01:03:50,069] {subprocess.py:92} INFO - 
[2023-03-10 01:03:50,070] {subprocess.py:92} INFO - During handling of the above exception, another exception occurred:
[2023-03-10 01:03:50,071] {subprocess.py:92} INFO - 
[2023-03-10 01:03:50,072] {subprocess.py:92} INFO - Traceback (most recent call last):
[2023-03-10 01:03:50,073] {subprocess.py:92} INFO -   File "/home/***/.local/lib/python3.7/site-packages/sqlalchemy/engine/base.py", line 3141, in _wrap_pool_connect
[2023-03-10 01:03:50,074] {subprocess.py:92} INFO -     return fn()
[2023-03-10 01:03:50,076] {subprocess.py:92} INFO -   File "/home/***/.local/lib/python3.7/site-packages/sqlalchemy/pool/base.py", line 301, in connect
[2023-03-10 01:03:50,076] {subprocess.py:92} INFO -     return _ConnectionFairy._checkout(self)
[2023-03-10 01:03:50,078] {subprocess.py:92} INFO -   File "/home/***/.local/lib/python3.7/site-packages/sqlalchemy/pool/base.py", line 755, in _checkout
[2023-03-10 01:03:50,079] {subprocess.py:92} INFO -     fairy = _ConnectionRecord.checkout(pool)
[2023-03-10 01:03:50,080] {subprocess.py:92} INFO -   File "/home/***/.local/lib/python3.7/site-packages/sqlalchemy/pool/base.py", line 419, in checkout
[2023-03-10 01:03:50,081] {subprocess.py:92} INFO -     rec = pool._do_get()
[2023-03-10 01:03:50,082] {subprocess.py:92} INFO -   File "/home/***/.local/lib/python3.7/site-packages/sqlalchemy/pool/impl.py", line 145, in _do_get
[2023-03-10 01:03:50,083] {subprocess.py:92} INFO -     self._dec_overflow()
[2023-03-10 01:03:50,084] {subprocess.py:92} INFO -   File "/home/***/.local/lib/python3.7/site-packages/sqlalchemy/util/langhelpers.py", line 72, in __exit__
[2023-03-10 01:03:50,085] {subprocess.py:92} INFO -     with_traceback=exc_tb,
[2023-03-10 01:03:50,086] {subprocess.py:92} INFO -   File "/home/***/.local/lib/python3.7/site-packages/sqlalchemy/util/compat.py", line 211, in raise_
[2023-03-10 01:03:50,087] {subprocess.py:92} INFO -     raise exception
[2023-03-10 01:03:50,087] {subprocess.py:92} INFO -   File "/home/***/.local/lib/python3.7/site-packages/sqlalchemy/pool/impl.py", line 142, in _do_get
[2023-03-10 01:03:50,088] {subprocess.py:92} INFO -     return self._create_connection()
[2023-03-10 01:03:50,089] {subprocess.py:92} INFO -   File "/home/***/.local/lib/python3.7/site-packages/sqlalchemy/pool/base.py", line 247, in _create_connection
[2023-03-10 01:03:50,090] {subprocess.py:92} INFO -     return _ConnectionRecord(self)
[2023-03-10 01:03:50,090] {subprocess.py:92} INFO -   File "/home/***/.local/lib/python3.7/site-packages/sqlalchemy/pool/base.py", line 362, in __init__
[2023-03-10 01:03:50,091] {subprocess.py:92} INFO -     self.__connect(first_connect_check=True)
[2023-03-10 01:03:50,091] {subprocess.py:92} INFO -   File "/home/***/.local/lib/python3.7/site-packages/sqlalchemy/pool/base.py", line 605, in __connect
[2023-03-10 01:03:50,092] {subprocess.py:92} INFO -     pool.logger.debug("Error on connect(): %s", e)
[2023-03-10 01:03:50,093] {subprocess.py:92} INFO -   File "/home/***/.local/lib/python3.7/site-packages/sqlalchemy/util/langhelpers.py", line 72, in __exit__
[2023-03-10 01:03:50,094] {subprocess.py:92} INFO -     with_traceback=exc_tb,
[2023-03-10 01:03:50,095] {subprocess.py:92} INFO -   File "/home/***/.local/lib/python3.7/site-packages/sqlalchemy/util/compat.py", line 211, in raise_
[2023-03-10 01:03:50,096] {subprocess.py:92} INFO -     raise exception
[2023-03-10 01:03:50,096] {subprocess.py:92} INFO -   File "/home/***/.local/lib/python3.7/site-packages/sqlalchemy/pool/base.py", line 599, in __connect
[2023-03-10 01:03:50,097] {subprocess.py:92} INFO -     connection = pool._invoke_creator(self)
[2023-03-10 01:03:50,098] {subprocess.py:92} INFO -   File "/home/***/.local/lib/python3.7/site-packages/sqlalchemy/engine/create.py", line 578, in connect
[2023-03-10 01:03:50,099] {subprocess.py:92} INFO -     return dialect.connect(*cargs, **cparams)
[2023-03-10 01:03:50,100] {subprocess.py:92} INFO -   File "/home/***/.local/lib/python3.7/site-packages/sqlalchemy/engine/default.py", line 583, in connect
[2023-03-10 01:03:50,101] {subprocess.py:92} INFO -     return self.dbapi.connect(*cargs, **cparams)
[2023-03-10 01:03:50,101] {subprocess.py:92} INFO -   File "/home/***/.local/lib/python3.7/site-packages/pymysql/connections.py", line 353, in __init__
[2023-03-10 01:03:50,102] {subprocess.py:92} INFO -     self.connect()
[2023-03-10 01:03:50,103] {subprocess.py:92} INFO -   File "/home/***/.local/lib/python3.7/site-packages/pymysql/connections.py", line 664, in connect
[2023-03-10 01:03:50,104] {subprocess.py:92} INFO -     raise exc
[2023-03-10 01:03:50,105] {subprocess.py:92} INFO - pymysql.err.OperationalError: (2003, "Can't connect to MySQL server on '127.0.0.1' ([Errno 111] Connection refused)")
[2023-03-10 01:03:50,105] {subprocess.py:92} INFO - 
[2023-03-10 01:03:50,107] {subprocess.py:92} INFO - The above exception was the direct cause of the following exception:
[2023-03-10 01:03:50,108] {subprocess.py:92} INFO - 
[2023-03-10 01:03:50,108] {subprocess.py:92} INFO - Traceback (most recent call last):
[2023-03-10 01:03:50,109] {subprocess.py:92} INFO -   File "/opt/***/dags/Proyecto/transform.py", line 32, in <module>
[2023-03-10 01:03:50,111] {subprocess.py:92} INFO -     load.load_mysql(df_enunciado1, "enunciado1")
[2023-03-10 01:03:50,111] {subprocess.py:92} INFO -   File "/opt/***/dags/Proyecto/process/load.py", line 28, in load_mysql
[2023-03-10 01:03:50,112] {subprocess.py:92} INFO -     u.df_to_mysql(df, u.mysql_engine(), db_tbl_name)
[2023-03-10 01:03:50,113] {subprocess.py:92} INFO -   File "/opt/***/dags/Proyecto/process/util/utils.py", line 59, in df_to_mysql
[2023-03-10 01:03:50,114] {subprocess.py:92} INFO -     df.to_sql(tbl_name, engine, if_exists='replace')
[2023-03-10 01:03:50,115] {subprocess.py:92} INFO -   File "/home/***/.local/lib/python3.7/site-packages/pandas/core/generic.py", line 2882, in to_sql
[2023-03-10 01:03:50,115] {subprocess.py:92} INFO -     method=method,
[2023-03-10 01:03:50,116] {subprocess.py:92} INFO -   File "/home/***/.local/lib/python3.7/site-packages/pandas/io/sql.py", line 728, in to_sql
[2023-03-10 01:03:50,117] {subprocess.py:92} INFO -     **engine_kwargs,
[2023-03-10 01:03:50,118] {subprocess.py:92} INFO -   File "/home/***/.local/lib/python3.7/site-packages/pandas/io/sql.py", line 1758, in to_sql
[2023-03-10 01:03:50,118] {subprocess.py:92} INFO -     dtype=dtype,
[2023-03-10 01:03:50,119] {subprocess.py:92} INFO -   File "/home/***/.local/lib/python3.7/site-packages/pandas/io/sql.py", line 1650, in prep_table
[2023-03-10 01:03:50,120] {subprocess.py:92} INFO -     table.create()
[2023-03-10 01:03:50,121] {subprocess.py:92} INFO -   File "/home/***/.local/lib/python3.7/site-packages/pandas/io/sql.py", line 856, in create
[2023-03-10 01:03:50,121] {subprocess.py:92} INFO -     if self.exists():
[2023-03-10 01:03:50,122] {subprocess.py:92} INFO -   File "/home/***/.local/lib/python3.7/site-packages/pandas/io/sql.py", line 840, in exists
[2023-03-10 01:03:50,123] {subprocess.py:92} INFO -     return self.pd_sql.has_table(self.name, self.schema)
[2023-03-10 01:03:50,124] {subprocess.py:92} INFO -   File "/home/***/.local/lib/python3.7/site-packages/pandas/io/sql.py", line 1783, in has_table
[2023-03-10 01:03:50,125] {subprocess.py:92} INFO -     insp = sa.inspect(self.connectable)
[2023-03-10 01:03:50,125] {subprocess.py:92} INFO -   File "/home/***/.local/lib/python3.7/site-packages/sqlalchemy/inspection.py", line 64, in inspect
[2023-03-10 01:03:50,126] {subprocess.py:92} INFO -     ret = reg(subject)
[2023-03-10 01:03:50,127] {subprocess.py:92} INFO -   File "/home/***/.local/lib/python3.7/site-packages/sqlalchemy/engine/reflection.py", line 182, in _engine_insp
[2023-03-10 01:03:50,128] {subprocess.py:92} INFO -     return Inspector._construct(Inspector._init_engine, bind)
[2023-03-10 01:03:50,129] {subprocess.py:92} INFO -   File "/home/***/.local/lib/python3.7/site-packages/sqlalchemy/engine/reflection.py", line 117, in _construct
[2023-03-10 01:03:50,129] {subprocess.py:92} INFO -     init(self, bind)
[2023-03-10 01:03:50,130] {subprocess.py:92} INFO -   File "/home/***/.local/lib/python3.7/site-packages/sqlalchemy/engine/reflection.py", line 128, in _init_engine
[2023-03-10 01:03:50,131] {subprocess.py:92} INFO -     engine.connect().close()
[2023-03-10 01:03:50,131] {subprocess.py:92} INFO -   File "/home/***/.local/lib/python3.7/site-packages/sqlalchemy/engine/base.py", line 3095, in connect
[2023-03-10 01:03:50,132] {subprocess.py:92} INFO -     return self._connection_cls(self, close_with_result=close_with_result)
[2023-03-10 01:03:50,133] {subprocess.py:92} INFO -   File "/home/***/.local/lib/python3.7/site-packages/sqlalchemy/engine/base.py", line 91, in __init__
[2023-03-10 01:03:50,134] {subprocess.py:92} INFO -     else engine.raw_connection()
[2023-03-10 01:03:50,135] {subprocess.py:92} INFO -   File "/home/***/.local/lib/python3.7/site-packages/sqlalchemy/engine/base.py", line 3174, in raw_connection
[2023-03-10 01:03:50,136] {subprocess.py:92} INFO -     return self._wrap_pool_connect(self.pool.connect, _connection)
[2023-03-10 01:03:50,137] {subprocess.py:92} INFO -   File "/home/***/.local/lib/python3.7/site-packages/sqlalchemy/engine/base.py", line 3145, in _wrap_pool_connect
[2023-03-10 01:03:50,137] {subprocess.py:92} INFO -     e, dialect, self
[2023-03-10 01:03:50,138] {subprocess.py:92} INFO -   File "/home/***/.local/lib/python3.7/site-packages/sqlalchemy/engine/base.py", line 2004, in _handle_dbapi_exception_noconnection
[2023-03-10 01:03:50,139] {subprocess.py:92} INFO -     sqlalchemy_exception, with_traceback=exc_info[2], from_=e
[2023-03-10 01:03:50,139] {subprocess.py:92} INFO -   File "/home/***/.local/lib/python3.7/site-packages/sqlalchemy/util/compat.py", line 211, in raise_
[2023-03-10 01:03:50,140] {subprocess.py:92} INFO -     raise exception
[2023-03-10 01:03:50,141] {subprocess.py:92} INFO -   File "/home/***/.local/lib/python3.7/site-packages/sqlalchemy/engine/base.py", line 3141, in _wrap_pool_connect
[2023-03-10 01:03:50,141] {subprocess.py:92} INFO -     return fn()
[2023-03-10 01:03:50,142] {subprocess.py:92} INFO -   File "/home/***/.local/lib/python3.7/site-packages/sqlalchemy/pool/base.py", line 301, in connect
[2023-03-10 01:03:50,143] {subprocess.py:92} INFO -     return _ConnectionFairy._checkout(self)
[2023-03-10 01:03:50,144] {subprocess.py:92} INFO -   File "/home/***/.local/lib/python3.7/site-packages/sqlalchemy/pool/base.py", line 755, in _checkout
[2023-03-10 01:03:50,145] {subprocess.py:92} INFO -     fairy = _ConnectionRecord.checkout(pool)
[2023-03-10 01:03:50,145] {subprocess.py:92} INFO -   File "/home/***/.local/lib/python3.7/site-packages/sqlalchemy/pool/base.py", line 419, in checkout
[2023-03-10 01:03:50,146] {subprocess.py:92} INFO -     rec = pool._do_get()
[2023-03-10 01:03:50,147] {subprocess.py:92} INFO -   File "/home/***/.local/lib/python3.7/site-packages/sqlalchemy/pool/impl.py", line 145, in _do_get
[2023-03-10 01:03:50,148] {subprocess.py:92} INFO -     self._dec_overflow()
[2023-03-10 01:03:50,149] {subprocess.py:92} INFO -   File "/home/***/.local/lib/python3.7/site-packages/sqlalchemy/util/langhelpers.py", line 72, in __exit__
[2023-03-10 01:03:50,150] {subprocess.py:92} INFO -     with_traceback=exc_tb,
[2023-03-10 01:03:50,151] {subprocess.py:92} INFO -   File "/home/***/.local/lib/python3.7/site-packages/sqlalchemy/util/compat.py", line 211, in raise_
[2023-03-10 01:03:50,155] {subprocess.py:92} INFO -     raise exception
[2023-03-10 01:03:50,156] {subprocess.py:92} INFO -   File "/home/***/.local/lib/python3.7/site-packages/sqlalchemy/pool/impl.py", line 142, in _do_get
[2023-03-10 01:03:50,157] {subprocess.py:92} INFO -     return self._create_connection()
[2023-03-10 01:03:50,159] {subprocess.py:92} INFO -   File "/home/***/.local/lib/python3.7/site-packages/sqlalchemy/pool/base.py", line 247, in _create_connection
[2023-03-10 01:03:50,160] {subprocess.py:92} INFO -     return _ConnectionRecord(self)
[2023-03-10 01:03:50,161] {subprocess.py:92} INFO -   File "/home/***/.local/lib/python3.7/site-packages/sqlalchemy/pool/base.py", line 362, in __init__
[2023-03-10 01:03:50,162] {subprocess.py:92} INFO -     self.__connect(first_connect_check=True)
[2023-03-10 01:03:50,162] {subprocess.py:92} INFO -   File "/home/***/.local/lib/python3.7/site-packages/sqlalchemy/pool/base.py", line 605, in __connect
[2023-03-10 01:03:50,163] {subprocess.py:92} INFO -     pool.logger.debug("Error on connect(): %s", e)
[2023-03-10 01:03:50,163] {subprocess.py:92} INFO -   File "/home/***/.local/lib/python3.7/site-packages/sqlalchemy/util/langhelpers.py", line 72, in __exit__
[2023-03-10 01:03:50,165] {subprocess.py:92} INFO -     with_traceback=exc_tb,
[2023-03-10 01:03:50,166] {subprocess.py:92} INFO -   File "/home/***/.local/lib/python3.7/site-packages/sqlalchemy/util/compat.py", line 211, in raise_
[2023-03-10 01:03:50,167] {subprocess.py:92} INFO -     raise exception
[2023-03-10 01:03:50,168] {subprocess.py:92} INFO -   File "/home/***/.local/lib/python3.7/site-packages/sqlalchemy/pool/base.py", line 599, in __connect
[2023-03-10 01:03:50,170] {subprocess.py:92} INFO -     connection = pool._invoke_creator(self)
[2023-03-10 01:03:50,171] {subprocess.py:92} INFO -   File "/home/***/.local/lib/python3.7/site-packages/sqlalchemy/engine/create.py", line 578, in connect
[2023-03-10 01:03:50,172] {subprocess.py:92} INFO -     return dialect.connect(*cargs, **cparams)
[2023-03-10 01:03:50,173] {subprocess.py:92} INFO -   File "/home/***/.local/lib/python3.7/site-packages/sqlalchemy/engine/default.py", line 583, in connect
[2023-03-10 01:03:50,175] {subprocess.py:92} INFO -     return self.dbapi.connect(*cargs, **cparams)
[2023-03-10 01:03:50,176] {subprocess.py:92} INFO -   File "/home/***/.local/lib/python3.7/site-packages/pymysql/connections.py", line 353, in __init__
[2023-03-10 01:03:50,177] {subprocess.py:92} INFO -     self.connect()
[2023-03-10 01:03:50,179] {subprocess.py:92} INFO -   File "/home/***/.local/lib/python3.7/site-packages/pymysql/connections.py", line 664, in connect
[2023-03-10 01:03:50,180] {subprocess.py:92} INFO -     raise exc
[2023-03-10 01:03:50,181] {subprocess.py:92} INFO - sqlalchemy.exc.OperationalError: (pymysql.err.OperationalError) (2003, "Can't connect to MySQL server on '127.0.0.1' ([Errno 111] Connection refused)")
[2023-03-10 01:03:50,182] {subprocess.py:92} INFO - (Background on this error at: http://sqlalche.me/e/14/e3q8)
[2023-03-10 01:03:50,217] {subprocess.py:96} INFO - Command exited with return code 1
[2023-03-10 01:03:50,229] {taskinstance.py:1889} ERROR - Task failed with exception
Traceback (most recent call last):
  File "/home/airflow/.local/lib/python3.7/site-packages/airflow/operators/bash.py", line 195, in execute
    f'Bash command failed. The command returned a non-zero exit code {result.exit_code}.'
airflow.exceptions.AirflowException: Bash command failed. The command returned a non-zero exit code 1.
[2023-03-10 01:03:50,232] {taskinstance.py:1400} INFO - Marking task as FAILED. dag_id=pipeline_bash_operator, task_id=run_script_transform, execution_date=20230310T010300, start_date=20230310T010321, end_date=20230310T010350
[2023-03-10 01:03:50,241] {standard_task_runner.py:97} ERROR - Failed to execute job 69 for task run_script_transform (Bash command failed. The command returned a non-zero exit code 1.; 796)
[2023-03-10 01:03:50,261] {local_task_job.py:156} INFO - Task exited with return code 1
[2023-03-10 01:03:50,277] {local_task_job.py:273} INFO - 0 downstream tasks scheduled from follow-on schedule check
