[2023-03-04 16:37:47,144] {taskinstance.py:1159} INFO - Dependencies all met for <TaskInstance: simple_etl_dag.run_etl_task scheduled__2023-03-03T00:00:00+00:00 [queued]>
[2023-03-04 16:37:47,149] {taskinstance.py:1159} INFO - Dependencies all met for <TaskInstance: simple_etl_dag.run_etl_task scheduled__2023-03-03T00:00:00+00:00 [queued]>
[2023-03-04 16:37:47,150] {taskinstance.py:1356} INFO - 
--------------------------------------------------------------------------------
[2023-03-04 16:37:47,151] {taskinstance.py:1357} INFO - Starting attempt 1 of 1
[2023-03-04 16:37:47,152] {taskinstance.py:1358} INFO - 
--------------------------------------------------------------------------------
[2023-03-04 16:37:47,161] {taskinstance.py:1377} INFO - Executing <Task(PythonOperator): run_etl_task> on 2023-03-03 00:00:00+00:00
[2023-03-04 16:37:47,167] {standard_task_runner.py:52} INFO - Started process 562 to run task
[2023-03-04 16:37:47,170] {standard_task_runner.py:79} INFO - Running: ['***', 'tasks', 'run', 'simple_etl_dag', 'run_etl_task', 'scheduled__2023-03-03T00:00:00+00:00', '--job-id', '2', '--raw', '--subdir', 'DAGS_FOLDER/simple_etl_dag.py', '--cfg-path', '/tmp/tmpn1jld70v', '--error-file', '/tmp/tmpp0xjyllz']
[2023-03-04 16:37:47,173] {standard_task_runner.py:80} INFO - Job 2: Subtask run_etl_task
[2023-03-04 16:37:47,216] {task_command.py:369} INFO - Running <TaskInstance: simple_etl_dag.run_etl_task scheduled__2023-03-03T00:00:00+00:00 [running]> on host 004ed28f4a99
[2023-03-04 16:37:47,263] {taskinstance.py:1571} INFO - Exporting the following env vars:
AIRFLOW_CTX_DAG_OWNER=Americo
AIRFLOW_CTX_DAG_ID=simple_etl_dag
AIRFLOW_CTX_TASK_ID=run_etl_task
AIRFLOW_CTX_EXECUTION_DATE=2023-03-03T00:00:00+00:00
AIRFLOW_CTX_TRY_NUMBER=1
AIRFLOW_CTX_DAG_RUN_ID=scheduled__2023-03-03T00:00:00+00:00
[2023-03-04 16:37:47,265] {logging_mixin.py:115} INFO - >>> Running 'etl' function. Logged at 2023-03-04 16:37:47.265213+00:00
[2023-03-04 16:37:47,266] {logging_mixin.py:115} INFO - >>> Running 'connect_db' function. Logged at 2023-03-04 16:37:47.266164+00:00
[2023-03-04 16:37:47,271] {logging_mixin.py:115} INFO - Connecting to DB
[2023-03-04 16:39:02,280] {taskinstance.py:1889} ERROR - Task failed with exception
Traceback (most recent call last):
  File "/home/airflow/.local/lib/python3.7/site-packages/sqlalchemy/engine/base.py", line 3141, in _wrap_pool_connect
    return fn()
  File "/home/airflow/.local/lib/python3.7/site-packages/sqlalchemy/pool/base.py", line 301, in connect
    return _ConnectionFairy._checkout(self)
  File "/home/airflow/.local/lib/python3.7/site-packages/sqlalchemy/pool/base.py", line 755, in _checkout
    fairy = _ConnectionRecord.checkout(pool)
  File "/home/airflow/.local/lib/python3.7/site-packages/sqlalchemy/pool/base.py", line 419, in checkout
    rec = pool._do_get()
  File "/home/airflow/.local/lib/python3.7/site-packages/sqlalchemy/pool/impl.py", line 145, in _do_get
    self._dec_overflow()
  File "/home/airflow/.local/lib/python3.7/site-packages/sqlalchemy/util/langhelpers.py", line 72, in __exit__
    with_traceback=exc_tb,
  File "/home/airflow/.local/lib/python3.7/site-packages/sqlalchemy/util/compat.py", line 211, in raise_
    raise exception
  File "/home/airflow/.local/lib/python3.7/site-packages/sqlalchemy/pool/impl.py", line 142, in _do_get
    return self._create_connection()
  File "/home/airflow/.local/lib/python3.7/site-packages/sqlalchemy/pool/base.py", line 247, in _create_connection
    return _ConnectionRecord(self)
  File "/home/airflow/.local/lib/python3.7/site-packages/sqlalchemy/pool/base.py", line 362, in __init__
    self.__connect(first_connect_check=True)
  File "/home/airflow/.local/lib/python3.7/site-packages/sqlalchemy/pool/base.py", line 605, in __connect
    pool.logger.debug("Error on connect(): %s", e)
  File "/home/airflow/.local/lib/python3.7/site-packages/sqlalchemy/util/langhelpers.py", line 72, in __exit__
    with_traceback=exc_tb,
  File "/home/airflow/.local/lib/python3.7/site-packages/sqlalchemy/util/compat.py", line 211, in raise_
    raise exception
  File "/home/airflow/.local/lib/python3.7/site-packages/sqlalchemy/pool/base.py", line 599, in __connect
    connection = pool._invoke_creator(self)
  File "/home/airflow/.local/lib/python3.7/site-packages/sqlalchemy/engine/create.py", line 578, in connect
    return dialect.connect(*cargs, **cparams)
  File "/home/airflow/.local/lib/python3.7/site-packages/sqlalchemy/engine/default.py", line 583, in connect
    return self.dbapi.connect(*cargs, **cparams)
  File "/home/airflow/.local/lib/python3.7/site-packages/psycopg2/__init__.py", line 122, in connect
    conn = _connect(dsn, connection_factory=connection_factory, **kwasync)
psycopg2.OperationalError: could not connect to server: Connection refused
	Is the server running on host "192.168.2.20" and accepting
	TCP/IP connections on port 5434?


The above exception was the direct cause of the following exception:

Traceback (most recent call last):
  File "/home/airflow/.local/lib/python3.7/site-packages/airflow/operators/python.py", line 171, in execute
    return_value = self.execute_callable()
  File "/home/airflow/.local/lib/python3.7/site-packages/airflow/operators/python.py", line 189, in execute_callable
    return self.python_callable(*self.op_args, **self.op_kwargs)
  File "/opt/airflow/dags/simple_etl_dag.py", line 30, in inner
    to_execute = fn(*args, **kwargs)
  File "/opt/airflow/dags/simple_etl_dag.py", line 93, in etl
    db_engine = connect_db()
  File "/opt/airflow/dags/simple_etl_dag.py", line 30, in inner
    to_execute = fn(*args, **kwargs)
  File "/opt/airflow/dags/simple_etl_dag.py", line 43, in connect_db
    engine.connect()
  File "/home/airflow/.local/lib/python3.7/site-packages/sqlalchemy/engine/base.py", line 3095, in connect
    return self._connection_cls(self, close_with_result=close_with_result)
  File "/home/airflow/.local/lib/python3.7/site-packages/sqlalchemy/engine/base.py", line 91, in __init__
    else engine.raw_connection()
  File "/home/airflow/.local/lib/python3.7/site-packages/sqlalchemy/engine/base.py", line 3174, in raw_connection
    return self._wrap_pool_connect(self.pool.connect, _connection)
  File "/home/airflow/.local/lib/python3.7/site-packages/sqlalchemy/engine/base.py", line 3145, in _wrap_pool_connect
    e, dialect, self
  File "/home/airflow/.local/lib/python3.7/site-packages/sqlalchemy/engine/base.py", line 2004, in _handle_dbapi_exception_noconnection
    sqlalchemy_exception, with_traceback=exc_info[2], from_=e
  File "/home/airflow/.local/lib/python3.7/site-packages/sqlalchemy/util/compat.py", line 211, in raise_
    raise exception
  File "/home/airflow/.local/lib/python3.7/site-packages/sqlalchemy/engine/base.py", line 3141, in _wrap_pool_connect
    return fn()
  File "/home/airflow/.local/lib/python3.7/site-packages/sqlalchemy/pool/base.py", line 301, in connect
    return _ConnectionFairy._checkout(self)
  File "/home/airflow/.local/lib/python3.7/site-packages/sqlalchemy/pool/base.py", line 755, in _checkout
    fairy = _ConnectionRecord.checkout(pool)
  File "/home/airflow/.local/lib/python3.7/site-packages/sqlalchemy/pool/base.py", line 419, in checkout
    rec = pool._do_get()
  File "/home/airflow/.local/lib/python3.7/site-packages/sqlalchemy/pool/impl.py", line 145, in _do_get
    self._dec_overflow()
  File "/home/airflow/.local/lib/python3.7/site-packages/sqlalchemy/util/langhelpers.py", line 72, in __exit__
    with_traceback=exc_tb,
  File "/home/airflow/.local/lib/python3.7/site-packages/sqlalchemy/util/compat.py", line 211, in raise_
    raise exception
  File "/home/airflow/.local/lib/python3.7/site-packages/sqlalchemy/pool/impl.py", line 142, in _do_get
    return self._create_connection()
  File "/home/airflow/.local/lib/python3.7/site-packages/sqlalchemy/pool/base.py", line 247, in _create_connection
    return _ConnectionRecord(self)
  File "/home/airflow/.local/lib/python3.7/site-packages/sqlalchemy/pool/base.py", line 362, in __init__
    self.__connect(first_connect_check=True)
  File "/home/airflow/.local/lib/python3.7/site-packages/sqlalchemy/pool/base.py", line 605, in __connect
    pool.logger.debug("Error on connect(): %s", e)
  File "/home/airflow/.local/lib/python3.7/site-packages/sqlalchemy/util/langhelpers.py", line 72, in __exit__
    with_traceback=exc_tb,
  File "/home/airflow/.local/lib/python3.7/site-packages/sqlalchemy/util/compat.py", line 211, in raise_
    raise exception
  File "/home/airflow/.local/lib/python3.7/site-packages/sqlalchemy/pool/base.py", line 599, in __connect
    connection = pool._invoke_creator(self)
  File "/home/airflow/.local/lib/python3.7/site-packages/sqlalchemy/engine/create.py", line 578, in connect
    return dialect.connect(*cargs, **cparams)
  File "/home/airflow/.local/lib/python3.7/site-packages/sqlalchemy/engine/default.py", line 583, in connect
    return self.dbapi.connect(*cargs, **cparams)
  File "/home/airflow/.local/lib/python3.7/site-packages/psycopg2/__init__.py", line 122, in connect
    conn = _connect(dsn, connection_factory=connection_factory, **kwasync)
sqlalchemy.exc.OperationalError: (psycopg2.OperationalError) could not connect to server: Connection refused
	Is the server running on host "192.168.2.20" and accepting
	TCP/IP connections on port 5434?

(Background on this error at: http://sqlalche.me/e/14/e3q8)
[2023-03-04 16:39:02,293] {taskinstance.py:1400} INFO - Marking task as FAILED. dag_id=simple_etl_dag, task_id=run_etl_task, execution_date=20230303T000000, start_date=20230304T163747, end_date=20230304T163902
[2023-03-04 16:39:02,301] {standard_task_runner.py:97} ERROR - Failed to execute job 2 for task run_etl_task ((psycopg2.OperationalError) could not connect to server: Connection refused
	Is the server running on host "192.168.2.20" and accepting
	TCP/IP connections on port 5434?

(Background on this error at: http://sqlalche.me/e/14/e3q8); 562)
[2023-03-04 16:39:02,313] {local_task_job.py:156} INFO - Task exited with return code 1
[2023-03-04 16:39:02,335] {local_task_job.py:273} INFO - 0 downstream tasks scheduled from follow-on schedule check
