[2023-03-05 02:22:49,344] {taskinstance.py:1159} INFO - Dependencies all met for <TaskInstance: mysqloperator_demo.CreateTable scheduled__2023-03-04T00:00:00+00:00 [queued]>
[2023-03-05 02:22:49,352] {taskinstance.py:1159} INFO - Dependencies all met for <TaskInstance: mysqloperator_demo.CreateTable scheduled__2023-03-04T00:00:00+00:00 [queued]>
[2023-03-05 02:22:49,354] {taskinstance.py:1356} INFO - 
--------------------------------------------------------------------------------
[2023-03-05 02:22:49,355] {taskinstance.py:1357} INFO - Starting attempt 1 of 1
[2023-03-05 02:22:49,356] {taskinstance.py:1358} INFO - 
--------------------------------------------------------------------------------
[2023-03-05 02:22:49,364] {taskinstance.py:1377} INFO - Executing <Task(MySqlOperator): CreateTable> on 2023-03-04 00:00:00+00:00
[2023-03-05 02:22:49,369] {standard_task_runner.py:52} INFO - Started process 1236 to run task
[2023-03-05 02:22:49,371] {standard_task_runner.py:79} INFO - Running: ['***', 'tasks', 'run', 'mysqloperator_demo', 'CreateTable', 'scheduled__2023-03-04T00:00:00+00:00', '--job-id', '29', '--raw', '--subdir', 'DAGS_FOLDER/mysqloperator.py', '--cfg-path', '/tmp/tmp0qdfmfw4', '--error-file', '/tmp/tmpt1evb37n']
[2023-03-05 02:22:49,373] {standard_task_runner.py:80} INFO - Job 29: Subtask CreateTable
[2023-03-05 02:22:49,411] {task_command.py:369} INFO - Running <TaskInstance: mysqloperator_demo.CreateTable scheduled__2023-03-04T00:00:00+00:00 [running]> on host 477ef5e408be
[2023-03-05 02:22:49,456] {taskinstance.py:1571} INFO - Exporting the following env vars:
AIRFLOW_CTX_DAG_OWNER=dezyre
AIRFLOW_CTX_DAG_ID=mysqloperator_demo
AIRFLOW_CTX_TASK_ID=CreateTable
AIRFLOW_CTX_EXECUTION_DATE=2023-03-04T00:00:00+00:00
AIRFLOW_CTX_TRY_NUMBER=1
AIRFLOW_CTX_DAG_RUN_ID=scheduled__2023-03-04T00:00:00+00:00
[2023-03-05 02:22:49,457] {mysql.py:82} INFO - Executing:  CREATE TABLE datapath4.employee(empid int, empname VARCHAR(25), salary int); 
[2023-03-05 02:22:49,472] {taskinstance.py:1889} ERROR - Task failed with exception
Traceback (most recent call last):
  File "/home/airflow/.local/lib/python3.7/site-packages/airflow/providers/mysql/operators/mysql.py", line 84, in execute
    hook.run(self.sql, autocommit=self.autocommit, parameters=self.parameters)
  File "/home/airflow/.local/lib/python3.7/site-packages/airflow/hooks/dbapi.py", line 181, in run
    with closing(self.get_conn()) as conn:
  File "/home/airflow/.local/lib/python3.7/site-packages/airflow/providers/mysql/hooks/mysql.py", line 158, in get_conn
    conn = self.connection or self.get_connection(getattr(self, self.conn_name_attr))
  File "/home/airflow/.local/lib/python3.7/site-packages/airflow/hooks/base.py", line 67, in get_connection
    conn = Connection.get_connection_from_secrets(conn_id)
  File "/home/airflow/.local/lib/python3.7/site-packages/airflow/models/connection.py", line 430, in get_connection_from_secrets
    raise AirflowNotFoundException(f"The conn_id `{conn_id}` isn't defined")
airflow.exceptions.AirflowNotFoundException: The conn_id `mysql_conn` isn't defined
[2023-03-05 02:22:49,476] {taskinstance.py:1400} INFO - Marking task as FAILED. dag_id=mysqloperator_demo, task_id=CreateTable, execution_date=20230304T000000, start_date=20230305T022249, end_date=20230305T022249
[2023-03-05 02:22:49,484] {standard_task_runner.py:97} ERROR - Failed to execute job 29 for task CreateTable (The conn_id `mysql_conn` isn't defined; 1236)
[2023-03-05 02:22:49,504] {local_task_job.py:156} INFO - Task exited with return code 1
[2023-03-05 02:22:49,532] {local_task_job.py:273} INFO - 0 downstream tasks scheduled from follow-on schedule check
