[2023-02-07 22:12:56,553] {taskinstance.py:1159} INFO - Dependencies all met for <TaskInstance: mysqloperator_demo.CreateTable manual__2023-02-07T22:12:55.464993+00:00 [queued]>
[2023-02-07 22:12:56,564] {taskinstance.py:1159} INFO - Dependencies all met for <TaskInstance: mysqloperator_demo.CreateTable manual__2023-02-07T22:12:55.464993+00:00 [queued]>
[2023-02-07 22:12:56,564] {taskinstance.py:1356} INFO - 
--------------------------------------------------------------------------------
[2023-02-07 22:12:56,565] {taskinstance.py:1357} INFO - Starting attempt 1 of 1
[2023-02-07 22:12:56,565] {taskinstance.py:1358} INFO - 
--------------------------------------------------------------------------------
[2023-02-07 22:12:56,581] {taskinstance.py:1377} INFO - Executing <Task(MySqlOperator): CreateTable> on 2023-02-07 22:12:55.464993+00:00
[2023-02-07 22:12:56,585] {standard_task_runner.py:52} INFO - Started process 317 to run task
[2023-02-07 22:12:56,587] {standard_task_runner.py:79} INFO - Running: ['***', 'tasks', 'run', 'mysqloperator_demo', 'CreateTable', 'manual__2023-02-07T22:12:55.464993+00:00', '--job-id', '2', '--raw', '--subdir', 'DAGS_FOLDER/mysqloperator.py', '--cfg-path', '/tmp/tmpr3n2fnqf', '--error-file', '/tmp/tmp7vjeyy5t']
[2023-02-07 22:12:56,588] {standard_task_runner.py:80} INFO - Job 2: Subtask CreateTable
[2023-02-07 22:12:56,665] {task_command.py:369} INFO - Running <TaskInstance: mysqloperator_demo.CreateTable manual__2023-02-07T22:12:55.464993+00:00 [running]> on host e8afdd2bd85b
[2023-02-07 22:12:56,783] {taskinstance.py:1571} INFO - Exporting the following env vars:
AIRFLOW_CTX_DAG_OWNER=dezyre
AIRFLOW_CTX_DAG_ID=mysqloperator_demo
AIRFLOW_CTX_TASK_ID=CreateTable
AIRFLOW_CTX_EXECUTION_DATE=2023-02-07T22:12:55.464993+00:00
AIRFLOW_CTX_TRY_NUMBER=1
AIRFLOW_CTX_DAG_RUN_ID=manual__2023-02-07T22:12:55.464993+00:00
[2023-02-07 22:12:56,783] {mysql.py:82} INFO - Executing:  CREATE TABLE datapath4.employee(empid int, empname VARCHAR(25), salary int); 
[2023-02-07 22:12:56,792] {base.py:68} INFO - Using connection ID 'mysql_conn' for task execution.
[2023-02-07 22:12:56,804] {dbapi.py:208} INFO - Running statement:  CREATE TABLE datapath4.employee(empid int, empname VARCHAR(25), salary int); , parameters: None
[2023-02-07 22:12:56,806] {taskinstance.py:1889} ERROR - Task failed with exception
Traceback (most recent call last):
  File "/home/airflow/.local/lib/python3.7/site-packages/airflow/providers/mysql/operators/mysql.py", line 84, in execute
    hook.run(self.sql, autocommit=self.autocommit, parameters=self.parameters)
  File "/home/airflow/.local/lib/python3.7/site-packages/airflow/hooks/dbapi.py", line 188, in run
    self._run_command(cur, sql_statement, parameters)
  File "/home/airflow/.local/lib/python3.7/site-packages/airflow/hooks/dbapi.py", line 212, in _run_command
    cur.execute(sql_statement)
  File "/home/airflow/.local/lib/python3.7/site-packages/MySQLdb/cursors.py", line 206, in execute
    res = self._query(query)
  File "/home/airflow/.local/lib/python3.7/site-packages/MySQLdb/cursors.py", line 319, in _query
    db.query(q)
  File "/home/airflow/.local/lib/python3.7/site-packages/MySQLdb/connections.py", line 254, in query
    _mysql.connection.query(self, query)
MySQLdb._exceptions.OperationalError: (1050, "Table 'employee' already exists")
[2023-02-07 22:12:56,812] {taskinstance.py:1400} INFO - Marking task as FAILED. dag_id=mysqloperator_demo, task_id=CreateTable, execution_date=20230207T221255, start_date=20230207T221256, end_date=20230207T221256
[2023-02-07 22:12:56,821] {standard_task_runner.py:97} ERROR - Failed to execute job 2 for task CreateTable ((1050, "Table 'employee' already exists"); 317)
[2023-02-07 22:12:56,839] {local_task_job.py:156} INFO - Task exited with return code 1
[2023-02-07 22:12:56,883] {local_task_job.py:273} INFO - 0 downstream tasks scheduled from follow-on schedule check
