[2023-03-10 02:21:16,021] {taskinstance.py:1159} INFO - Dependencies all met for <TaskInstance: pipeline_bash_operator.run_script_transform manual__2023-03-10T02:20:56.361742+00:00 [queued]>
[2023-03-10 02:21:16,028] {taskinstance.py:1159} INFO - Dependencies all met for <TaskInstance: pipeline_bash_operator.run_script_transform manual__2023-03-10T02:20:56.361742+00:00 [queued]>
[2023-03-10 02:21:16,029] {taskinstance.py:1356} INFO - 
--------------------------------------------------------------------------------
[2023-03-10 02:21:16,030] {taskinstance.py:1357} INFO - Starting attempt 1 of 1
[2023-03-10 02:21:16,031] {taskinstance.py:1358} INFO - 
--------------------------------------------------------------------------------
[2023-03-10 02:21:16,040] {taskinstance.py:1377} INFO - Executing <Task(BashOperator): run_script_transform> on 2023-03-10 02:20:56.361742+00:00
[2023-03-10 02:21:16,043] {standard_task_runner.py:52} INFO - Started process 2483 to run task
[2023-03-10 02:21:16,045] {standard_task_runner.py:79} INFO - Running: ['***', 'tasks', 'run', 'pipeline_bash_operator', 'run_script_transform', 'manual__2023-03-10T02:20:56.361742+00:00', '--job-id', '83', '--raw', '--subdir', 'DAGS_FOLDER/pipeline_bash_operator.py', '--cfg-path', '/tmp/tmpnues6zac', '--error-file', '/tmp/tmptmg923qw']
[2023-03-10 02:21:16,048] {standard_task_runner.py:80} INFO - Job 83: Subtask run_script_transform
[2023-03-10 02:21:16,085] {task_command.py:369} INFO - Running <TaskInstance: pipeline_bash_operator.run_script_transform manual__2023-03-10T02:20:56.361742+00:00 [running]> on host 477ef5e408be
[2023-03-10 02:21:16,129] {taskinstance.py:1571} INFO - Exporting the following env vars:
AIRFLOW_CTX_DAG_OWNER=Americo
AIRFLOW_CTX_DAG_ID=pipeline_bash_operator
AIRFLOW_CTX_TASK_ID=run_script_transform
AIRFLOW_CTX_EXECUTION_DATE=2023-03-10T02:20:56.361742+00:00
AIRFLOW_CTX_TRY_NUMBER=1
AIRFLOW_CTX_DAG_RUN_ID=manual__2023-03-10T02:20:56.361742+00:00
[2023-03-10 02:21:16,131] {subprocess.py:62} INFO - Tmp dir root location: 
 /tmp
[2023-03-10 02:21:16,132] {subprocess.py:74} INFO - Running command: ['bash', '-c', 'python /opt/***/dags/Proyecto/transform.py']
[2023-03-10 02:21:16,140] {subprocess.py:85} INFO - Output:
[2023-03-10 02:21:45,752] {subprocess.py:92} INFO - ingest loaded
[2023-03-10 02:21:45,754] {subprocess.py:92} INFO - loaded adsl landing
[2023-03-10 02:21:45,756] {subprocess.py:92} INFO - transform loaded
[2023-03-10 02:21:45,757] {subprocess.py:92} INFO - loaded adsl gold
[2023-03-10 02:21:45,759] {subprocess.py:92} INFO - Traceback (most recent call last):
[2023-03-10 02:21:45,760] {subprocess.py:92} INFO -   File "/opt/***/dags/Proyecto/transform.py", line 33, in <module>
[2023-03-10 02:21:45,761] {subprocess.py:92} INFO -     u.create_mysql_tbl_schema(df_enunciado1, u.mysql_conn(u.mysql_engine()), 'retail', "enunciado1")
[2023-03-10 02:21:45,762] {subprocess.py:92} INFO -   File "/opt/***/dags/Proyecto/process/util/utils.py", line 51, in create_mysql_tbl_schema
[2023-03-10 02:21:45,763] {subprocess.py:92} INFO -     cur.execute(sql)
[2023-03-10 02:21:45,764] {subprocess.py:92} INFO -   File "/home/***/.local/lib/python3.7/site-packages/pymysql/cursors.py", line 148, in execute
[2023-03-10 02:21:45,765] {subprocess.py:92} INFO -     result = self._query(query)
[2023-03-10 02:21:45,766] {subprocess.py:92} INFO -   File "/home/***/.local/lib/python3.7/site-packages/pymysql/cursors.py", line 310, in _query
[2023-03-10 02:21:45,767] {subprocess.py:92} INFO -     conn.query(q)
[2023-03-10 02:21:45,768] {subprocess.py:92} INFO -   File "/home/***/.local/lib/python3.7/site-packages/pymysql/connections.py", line 548, in query
[2023-03-10 02:21:45,769] {subprocess.py:92} INFO -     self._affected_rows = self._read_query_result(unbuffered=unbuffered)
[2023-03-10 02:21:45,770] {subprocess.py:92} INFO -   File "/home/***/.local/lib/python3.7/site-packages/pymysql/connections.py", line 775, in _read_query_result
[2023-03-10 02:21:45,771] {subprocess.py:92} INFO -     result.read()
[2023-03-10 02:21:45,772] {subprocess.py:92} INFO -   File "/home/***/.local/lib/python3.7/site-packages/pymysql/connections.py", line 1156, in read
[2023-03-10 02:21:45,775] {subprocess.py:92} INFO -     first_packet = self.connection._read_packet()
[2023-03-10 02:21:45,776] {subprocess.py:92} INFO -   File "/home/***/.local/lib/python3.7/site-packages/pymysql/connections.py", line 725, in _read_packet
[2023-03-10 02:21:45,777] {subprocess.py:92} INFO -     packet.raise_for_error()
[2023-03-10 02:21:45,778] {subprocess.py:92} INFO -   File "/home/***/.local/lib/python3.7/site-packages/pymysql/protocol.py", line 221, in raise_for_error
[2023-03-10 02:21:45,779] {subprocess.py:92} INFO -     err.raise_mysql_exception(self._data)
[2023-03-10 02:21:45,779] {subprocess.py:92} INFO -   File "/home/***/.local/lib/python3.7/site-packages/pymysql/err.py", line 143, in raise_mysql_exception
[2023-03-10 02:21:45,780] {subprocess.py:92} INFO -     raise errorclass(errno, errval)
[2023-03-10 02:21:45,781] {subprocess.py:92} INFO - pymysql.err.ProgrammingError: (1064, "You have an error in your SQL syntax; check the manual that corresponds to your MySQL server version for the right syntax to use near 'CREATE TABLE IF NOT EXISTS enunciado1 f(pi_db_uid INT AUTO_INCREMENT PRIMARY KEY' at line 1")
[2023-03-10 02:21:45,855] {subprocess.py:96} INFO - Command exited with return code 1
[2023-03-10 02:21:45,866] {taskinstance.py:1889} ERROR - Task failed with exception
Traceback (most recent call last):
  File "/home/airflow/.local/lib/python3.7/site-packages/airflow/operators/bash.py", line 195, in execute
    f'Bash command failed. The command returned a non-zero exit code {result.exit_code}.'
airflow.exceptions.AirflowException: Bash command failed. The command returned a non-zero exit code 1.
[2023-03-10 02:21:45,870] {taskinstance.py:1400} INFO - Marking task as FAILED. dag_id=pipeline_bash_operator, task_id=run_script_transform, execution_date=20230310T022056, start_date=20230310T022116, end_date=20230310T022145
[2023-03-10 02:21:45,879] {standard_task_runner.py:97} ERROR - Failed to execute job 83 for task run_script_transform (Bash command failed. The command returned a non-zero exit code 1.; 2483)
[2023-03-10 02:21:45,902] {local_task_job.py:156} INFO - Task exited with return code 1
[2023-03-10 02:21:45,919] {local_task_job.py:273} INFO - 0 downstream tasks scheduled from follow-on schedule check
