[2023-03-10 02:28:45,135] {taskinstance.py:1159} INFO - Dependencies all met for <TaskInstance: pipeline_bash_operator.run_script_transform manual__2023-03-10T02:28:24.459528+00:00 [queued]>
[2023-03-10 02:28:45,142] {taskinstance.py:1159} INFO - Dependencies all met for <TaskInstance: pipeline_bash_operator.run_script_transform manual__2023-03-10T02:28:24.459528+00:00 [queued]>
[2023-03-10 02:28:45,143] {taskinstance.py:1356} INFO - 
--------------------------------------------------------------------------------
[2023-03-10 02:28:45,144] {taskinstance.py:1357} INFO - Starting attempt 1 of 1
[2023-03-10 02:28:45,146] {taskinstance.py:1358} INFO - 
--------------------------------------------------------------------------------
[2023-03-10 02:28:45,155] {taskinstance.py:1377} INFO - Executing <Task(BashOperator): run_script_transform> on 2023-03-10 02:28:24.459528+00:00
[2023-03-10 02:28:45,159] {standard_task_runner.py:52} INFO - Started process 2705 to run task
[2023-03-10 02:28:45,162] {standard_task_runner.py:79} INFO - Running: ['***', 'tasks', 'run', 'pipeline_bash_operator', 'run_script_transform', 'manual__2023-03-10T02:28:24.459528+00:00', '--job-id', '91', '--raw', '--subdir', 'DAGS_FOLDER/pipeline_bash_operator.py', '--cfg-path', '/tmp/tmp26zeszjt', '--error-file', '/tmp/tmp9ebtl3ex']
[2023-03-10 02:28:45,163] {standard_task_runner.py:80} INFO - Job 91: Subtask run_script_transform
[2023-03-10 02:28:45,199] {task_command.py:369} INFO - Running <TaskInstance: pipeline_bash_operator.run_script_transform manual__2023-03-10T02:28:24.459528+00:00 [running]> on host 477ef5e408be
[2023-03-10 02:28:45,243] {taskinstance.py:1571} INFO - Exporting the following env vars:
AIRFLOW_CTX_DAG_OWNER=Americo
AIRFLOW_CTX_DAG_ID=pipeline_bash_operator
AIRFLOW_CTX_TASK_ID=run_script_transform
AIRFLOW_CTX_EXECUTION_DATE=2023-03-10T02:28:24.459528+00:00
AIRFLOW_CTX_TRY_NUMBER=1
AIRFLOW_CTX_DAG_RUN_ID=manual__2023-03-10T02:28:24.459528+00:00
[2023-03-10 02:28:45,245] {subprocess.py:62} INFO - Tmp dir root location: 
 /tmp
[2023-03-10 02:28:45,246] {subprocess.py:74} INFO - Running command: ['bash', '-c', 'python /opt/***/dags/Proyecto/transform.py']
[2023-03-10 02:28:45,254] {subprocess.py:85} INFO - Output:
[2023-03-10 02:29:12,001] {subprocess.py:92} INFO - ingest loaded
[2023-03-10 02:29:12,004] {subprocess.py:92} INFO - loaded adsl landing
[2023-03-10 02:29:12,005] {subprocess.py:92} INFO - transform loaded
[2023-03-10 02:29:12,007] {subprocess.py:92} INFO - loaded adsl gold
[2023-03-10 02:29:12,008] {subprocess.py:92} INFO - Traceback (most recent call last):
[2023-03-10 02:29:12,010] {subprocess.py:92} INFO -   File "/opt/***/dags/Proyecto/transform.py", line 33, in <module>
[2023-03-10 02:29:12,011] {subprocess.py:92} INFO -     u.create_mysql_tbl_schema(df_enunciado1, u.mysql_conn(u.mysql_engine()), 'retail', "enunciado1")
[2023-03-10 02:29:12,012] {subprocess.py:92} INFO -   File "/opt/***/dags/Proyecto/process/util/utils.py", line 51, in create_mysql_tbl_schema
[2023-03-10 02:29:12,013] {subprocess.py:92} INFO -     cur.execute(sql)
[2023-03-10 02:29:12,014] {subprocess.py:92} INFO -   File "/home/***/.local/lib/python3.7/site-packages/pymysql/cursors.py", line 148, in execute
[2023-03-10 02:29:12,015] {subprocess.py:92} INFO -     result = self._query(query)
[2023-03-10 02:29:12,016] {subprocess.py:92} INFO -   File "/home/***/.local/lib/python3.7/site-packages/pymysql/cursors.py", line 310, in _query
[2023-03-10 02:29:12,017] {subprocess.py:92} INFO -     conn.query(q)
[2023-03-10 02:29:12,018] {subprocess.py:92} INFO -   File "/home/***/.local/lib/python3.7/site-packages/pymysql/connections.py", line 548, in query
[2023-03-10 02:29:12,019] {subprocess.py:92} INFO -     self._affected_rows = self._read_query_result(unbuffered=unbuffered)
[2023-03-10 02:29:12,020] {subprocess.py:92} INFO -   File "/home/***/.local/lib/python3.7/site-packages/pymysql/connections.py", line 775, in _read_query_result
[2023-03-10 02:29:12,020] {subprocess.py:92} INFO -     result.read()
[2023-03-10 02:29:12,021] {subprocess.py:92} INFO -   File "/home/***/.local/lib/python3.7/site-packages/pymysql/connections.py", line 1156, in read
[2023-03-10 02:29:12,023] {subprocess.py:92} INFO -     first_packet = self.connection._read_packet()
[2023-03-10 02:29:12,024] {subprocess.py:92} INFO -   File "/home/***/.local/lib/python3.7/site-packages/pymysql/connections.py", line 725, in _read_packet
[2023-03-10 02:29:12,025] {subprocess.py:92} INFO -     packet.raise_for_error()
[2023-03-10 02:29:12,026] {subprocess.py:92} INFO -   File "/home/***/.local/lib/python3.7/site-packages/pymysql/protocol.py", line 221, in raise_for_error
[2023-03-10 02:29:12,027] {subprocess.py:92} INFO -     err.raise_mysql_exception(self._data)
[2023-03-10 02:29:12,028] {subprocess.py:92} INFO -   File "/home/***/.local/lib/python3.7/site-packages/pymysql/err.py", line 143, in raise_mysql_exception
[2023-03-10 02:29:12,034] {subprocess.py:92} INFO -     raise errorclass(errno, errval)
[2023-03-10 02:29:12,035] {subprocess.py:92} INFO - pymysql.err.ProgrammingError: (1064, "You have an error in your SQL syntax; check the manual that corresponds to your MySQL server version for the right syntax to use near 'CREATE TABLE IF NOT EXISTS enunciado1 (pi_db_uid INT AUTO_INCREMENT PRIMARY KEY)' at line 1")
[2023-03-10 02:29:12,134] {subprocess.py:96} INFO - Command exited with return code 1
[2023-03-10 02:29:12,146] {taskinstance.py:1889} ERROR - Task failed with exception
Traceback (most recent call last):
  File "/home/airflow/.local/lib/python3.7/site-packages/airflow/operators/bash.py", line 195, in execute
    f'Bash command failed. The command returned a non-zero exit code {result.exit_code}.'
airflow.exceptions.AirflowException: Bash command failed. The command returned a non-zero exit code 1.
[2023-03-10 02:29:12,149] {taskinstance.py:1400} INFO - Marking task as FAILED. dag_id=pipeline_bash_operator, task_id=run_script_transform, execution_date=20230310T022824, start_date=20230310T022845, end_date=20230310T022912
[2023-03-10 02:29:12,157] {standard_task_runner.py:97} ERROR - Failed to execute job 91 for task run_script_transform (Bash command failed. The command returned a non-zero exit code 1.; 2705)
[2023-03-10 02:29:12,169] {local_task_job.py:156} INFO - Task exited with return code 1
[2023-03-10 02:29:12,186] {local_task_job.py:273} INFO - 0 downstream tasks scheduled from follow-on schedule check
